Workbook
Name ExternalData_1: 内線通話!$A$1:$BV$1525
Name ExternalData_10: 内線通話!$A$8411:$BV$9391
Name ExternalData_11: 内線通話!$A$1:$BS$1525
Name ExternalData_12: 内線通話!$A$1:$BP$982
Name ExternalData_13: 内線通話!$A$1:$BM$848
Name ExternalData_14: 内線通話!$A$1:$BJ$862
Name ExternalData_15: 内線通話!$A$1:$BG$1425
Name ExternalData_16: 内線通話!$A$1:$BD$1
Name ExternalData_17: 内線通話!$A$1:$BA$1479
Name ExternalData_18: 内線通話!$A$1:$AX$485
Name ExternalData_19: 内線通話!$A$1:$AU$940
Name ExternalData_2: 内線通話!$A$1526:$BV$2372
Name ExternalData_20: 内線通話!$A$1:$AR$853
Name ExternalData_21: 内線通話!$A$1:$AO$1525
Name ExternalData_22: 内線通話!$A$1:$AL$848
Name ExternalData_23: 内線通話!$A$1:$AI$862
Name ExternalData_24: 内線通話!$A$1:$AF$1425
Name ExternalData_25: 内線通話!$A$1:$AC$1
Name ExternalData_26: 内線通話!$A$1:$Z$1479
Name ExternalData_27: 内線通話!$A$1:$W$485
Name ExternalData_28: 内線通話!$A$1:$T$940
Name ExternalData_29: 内線通話!$A$1:$Q$853
Name ExternalData_3: 内線通話!$A$2373:$BV$3233
Name ExternalData_30: 内線通話!$A$1:$N$982
Name ExternalData_31: 内線通話!$A$1:$K$1676
Name ExternalData_4: 内線通話!$A$3234:$BV$4657
Name ExternalData_5: 内線通話!$A$4658
Name ExternalData_6: 内線通話!$A$4658:$BV$6135
Name ExternalData_7: 内線通話!$A$6136:$BV$6619
Name ExternalData_8: 内線通話!$A$6620:$BV$7558
Name ExternalData_9: 内線通話!$A$7559:$BV$8410

Sheet 内線通話
A1: 時刻 | B1: 発信番号 | C1: 発信者 | D1: 着信番号 | E1: 着信者 | F1: 最終着信番号 | G1: 最終着信者 | H1: 通話時間（応答までの時間を含む） 数値に変換！！ | I1: 通話時間 数値に変換！！ | J1: メモ | K1: リクエストID
A2: 45933.787 | B2: 1003 | C2: =IFERROR(VLOOKUP(B2,[1]電話端末!$A$2:$E$284,2,FALSE),"不在") -> 【本社経理】池上有花 | D2: 2027 | E2: =IFERROR(VLOOKUP(D2,[1]電話端末!$A$2:$E$284,2,FALSE),"不在") -> 【MF大阪】平山孝潤 | F2: 2027 | G2: =IFERROR(VLOOKUP(F2,[1]電話端末!$A$2:$D$284,2,FALSE),"不在") -> 【MF大阪】平山孝潤 | H2: 29 | I2: 25 | K2: 2.5100301e+19
A3: 45933.77 | B3: 3453 | C3: =IFERROR(VLOOKUP(B3,[1]電話端末!$A$2:$E$284,2,FALSE),"不在") -> 【大阪】川越良隆 | D3: 3502 | E3: =IFERROR(VLOOKUP(D3,[1]電話端末!$A$2:$E$284,2,FALSE),"不在") -> 【岡山】伊藤優 | F3: 3502 | G3: =IFERROR(VLOOKUP(F3,[1]電話端末!$A$2:$D$284,2,FALSE),"不在") -> 【岡山】伊藤優 | H3: 27 | I3: 25 | K3: 2.5100301e+19
A4: 45933.759 | B4: 2027 | C4: =IFERROR(VLOOKUP(B4,[1]電話端末!$A$2:$E$284,2,FALSE),"不在") -> 【MF大阪】平山孝潤 | D4: 3060 | E4: =IFERROR(VLOOKUP(D4,[1]電話端末!$A$2:$E$284,2,FALSE),"不在") -> 【本社社長】鈴木正則 | G4: =IFERROR(VLOOKUP(F4,[1]電話端末!$A$2:$D$284,2,FALSE),"不在") -> 不在 | H4: 18 | I4: 0 | K4: 2.5100301e+19
A5: 45933.74 | B5: 3008 | C5: =IFERROR(VLOOKUP(B5,[1]電話端末!$A$2:$E$284,2,FALSE),"不在") -> 【東京】片桐芳夫 | D5: 0906153 | E5: =IFERROR(VLOOKUP(D5,[1]電話端末!$A$2:$E$284,2,FALSE),"不在") -> 不在 | G5: =IFERROR(VLOOKUP(F5,[1]電話端末!$A$2:$D$284,2,FALSE),"不在") -> 不在 | H5: 0 | I5: 0 | K5: 2.5100301e+19
A6: 45933.739 | B6: 3550 | C6: =IFERROR(VLOOKUP(B6,[1]電話端末!$A$2:$E$284,2,FALSE),"不在") -> 【広島】藤原輝己 | D6: 3603 | E6: =IFERROR(VLOOKUP(D6,[1]電話端末!$A$2:$E$284,2,FALSE),"不在") -> 【福岡】重松宝成 | F6: 3603 | G6: =IFERROR(VLOOKUP(F6,[1]電話端末!$A$2:$D$284,2,FALSE),"不在") -> 【福岡】重松宝成 | H6: 81 | I6: 76 | K6: 2.5100301e+19
A7: 45933.738 | B7: 1123 | C7: =IFERROR(VLOOKUP(B7,[1]電話端末!$A$2:$E$284,2,FALSE),"不在") -> 【本社IT】梶ヶ谷知晃 | D7: 3007 | E7: =IFERROR(VLOOKUP(D7,[1]電話端末!$A$2:$E$284,2,FALSE),"不在") -> 【東京】浦野鉄平 | F7: 3000 | G7: =IFERROR(VLOOKUP(F7,[1]電話端末!$A$2:$D$284,2,FALSE),"不在") -> 【東京】西垣彩 | H7: 50 | I7: 34 | K7: 2.5100301e+19
A8: 45933.737 | B8: 3052 | C8: =IFERROR(VLOOKUP(B8,[1]電話端末!$A$2:$E$284,2,FALSE),"不在") -> 【本社購買】山口泰彦 | D8: 2023 | E8: =IFERROR(VLOOKUP(D8,[1]電話端末!$A$2:$E$284,2,FALSE),"不在") -> 【MF大阪】内田優美 | F8: 2023 | G8: =IFERROR(VLOOKUP(F8,[1]電話端末!$A$2:$D$284,2,FALSE),"不在") -> 【MF大阪】内田優美 | H8: 73 | I8: 68 | K8: 2.5100301e+19
A9: 45933.736 | B9: 3151 | C9: =IFERROR(VLOOKUP(B9,[1]電話端末!$A$2:$E$284,2,FALSE),"不在") -> 【埼玉】池田千恵子 | D9: 3650 | E9: =IFERROR(VLOOKUP(D9,[1]電話端末!$A$2:$E$284,2,FALSE),"不在") -> 【北関東】高井翔斗 | F9: 3650 | G9: =IFERROR(VLOOKUP(F9,[1]電話端末!$A$2:$D$284,2,FALSE),"不在") -> 【北関東】高井翔斗 | H9: 281 | I9: 275 | K9: 2.5100301e+19
A10: 45933.734 | B10: 3059 | C10: =IFERROR(VLOOKUP(B10,[1]電話端末!$A$2:$E$284,2,FALSE),"不在") -> 【本社在庫物流課】黒田靖広 | D10: 3352 | E10: =IFERROR(VLOOKUP(D10,[1]電話端末!$A$2:$E$284,2,FALSE),"不在") -> 【名古屋】大渕温子 | F10: 3352 | G10: =IFERROR(VLOOKUP(F10,[1]電話端末!$A$2:$D$284,2,FALSE),"不在") -> 【名古屋】大渕温子 | H10: 109 | I10: 107 | K10: 2.5100301e+19
A11: 45933.731 | B11: 1003 | C11: =IFERROR(VLOOKUP(B11,[1]電話端末!$A$2:$E$284,2,FALSE),"不在") -> 【本社経理】池上有花 | D11: 1134 | E11: =IFERROR(VLOOKUP(D11,[1]電話端末!$A$2:$E$284,2,FALSE),"不在") -> 【本社EC】大城明日香 | F11: 1134 | G11: =IFERROR(VLOOKUP(F11,[1]電話端末!$A$2:$D$284,2,FALSE),"不在") -> 【本社EC】大城明日香 | H11: 166 | I11: 161 | K11: 2.5100301e+19
A12: 45933.73 | B12: 3102 | C12: =IFERROR(VLOOKUP(B12,[1]電話端末!$A$2:$E$284,2,FALSE),"不在") -> 【横浜】吉田玲 | D12: 5000 | E12: =IFERROR(VLOOKUP(D12,[1]電話端末!$A$2:$E$284,2,FALSE),"不在") -> 【千葉】着信グループ | F12: 3304 | G12: =IFERROR(VLOOKUP(F12,[1]電話端末!$A$2:$D$284,2,FALSE),"不在") -> 【千葉】遠藤和行 | H12: 46 | I12: 43 | K12: 2.5100301e+19
A13: 45933.729 | B13: 1134 | C13: =IFERROR(VLOOKUP(B13,[1]電話端末!$A$2:$E$284,2,FALSE),"不在") -> 【本社EC】大城明日香 | D13: 1155 | E13: =IFERROR(VLOOKUP(D13,[1]電話端末!$A$2:$E$284,2,FALSE),"不在") -> 【本社経理】池上有花 | F13: 1003 | G13: =IFERROR(VLOOKUP(F13,[1]電話端末!$A$2:$D$284,2,FALSE),"不在") -> 【本社経理】池上有花 | H13: 43 | I13: 40 | K13: 2.5100301e+19
A14: 45933.729 | B14: 3650 | C14: =IFERROR(VLOOKUP(B14,[1]電話端末!$A$2:$E$284,2,FALSE),"不在") -> 【北関東】高井翔斗 | D14: 3152 | E14: =IFERROR(VLOOKUP(D14,[1]電話端末!$A$2:$E$284,2,FALSE),"不在") -> 【埼玉】細田昌子 | F14: 3152 | G14: =IFERROR(VLOOKUP(F14,[1]電話端末!$A$2:$D$284,2,FALSE),"不在") -> 【埼玉】細田昌子 | H14: 88 | I14: 86 | K14: 2.5100301e+19
A15: 45933.729 | B15: 3551 | C15: =IFERROR(VLOOKUP(B15,[1]電話端末!$A$2:$E$284,2,FALSE),"不在") -> 【広島】小先純平 | D15: 3603 | E15: =IFERROR(VLOOKUP(D15,[1]電話端末!$A$2:$E$284,2,FALSE),"不在") -> 【福岡】重松宝成 | F15: 3603 | G15: =IFERROR(VLOOKUP(F15,[1]電話端末!$A$2:$D$284,2,FALSE),"不在") -> 【福岡】重松宝成 | H15: 26 | I15: 22 | K15: 2.5100301e+19
A16: 45933.725 | B16: 3551 | C16: =IFERROR(VLOOKUP(B16,[1]電話端末!$A$2:$E$284,2,FALSE),"不在") -> 【広島】小先純平 | D16: 3603 | E16: =IFERROR(VLOOKUP(D16,[1]電話端末!$A$2:$E$284,2,FALSE),"不在") -> 【福岡】重松宝成 | F16: 3603 | G16: =IFERROR(VLOOKUP(F16,[1]電話端末!$A$2:$D$284,2,FALSE),"不在") -> 【福岡】重松宝成 | H16: 69 | I16: 64 | K16: 2.5100301e+19
A17: 45933.723 | B17: 3350 | C17: =IFERROR(VLOOKUP(B17,[1]電話端末!$A$2:$E$284,2,FALSE),"不在") -> 【名古屋】稲垣みちる | D17: 3352 | E17: =IFERROR(VLOOKUP(D17,[1]電話端末!$A$2:$E$284,2,FALSE),"不在") -> 【名古屋】大渕温子 | F17: 3352 | G17: =IFERROR(VLOOKUP(F17,[1]電話端末!$A$2:$D$284,2,FALSE),"不在") -> 【名古屋】大渕温子 | H17: 30 | I17: 29 | K17: 2.5100301e+19
... A26: 45933.713 | B26: 3600 | C26: =IFERROR(VLOOKUP(B26,[1]電話端末!$A$2:$E$284,2,FALSE),"不在") -> 【福岡】松尾明日香 | D26: 3604 | E26: =IFERROR(VLOOKUP(D26,[1]電話端末!$A$2:$E$284,2,FALSE),"不在") -> 【福岡】奥薗美和 | F26: 3604 | G26: =IFERROR(VLOOKUP(F26,[1]電話端末!$A$2:$D$284,2,FALSE),"不在") -> 【福岡】奥薗美和 | H26: 40 | I26: 39 | K26: 2.5100301e+19
A27: 45933.711 | B27: 3508 | C27: =IFERROR(VLOOKUP(B27,[1]電話端末!$A$2:$E$284,2,FALSE),"不在") -> 【岡山】岸本麻衣子 | D27: 5271 | E27: =IFERROR(VLOOKUP(D27,[1]電話端末!$A$2:$E$284,2,FALSE),"不在") -> 不在 | G27: =IFERROR(VLOOKUP(F27,[1]電話端末!$A$2:$D$284,2,FALSE),"不在") -> 不在 | H27: 0 | I27: 0 | K27: 2.5100301e+19
A28: 45933.71 | B28: 3602 | C28: =IFERROR(VLOOKUP(B28,[1]電話端末!$A$2:$E$284,2,FALSE),"不在") -> 【福岡】山崎芹奈 | D28: 3604 | E28: =IFERROR(VLOOKUP(D28,[1]電話端末!$A$2:$E$284,2,FALSE),"不在") -> 【福岡】奥薗美和 | F28: 3604 | G28: =IFERROR(VLOOKUP(F28,[1]電話端末!$A$2:$D$284,2,FALSE),"不在") -> 【福岡】奥薗美和 | H28: 49 | I28: 47 | K28: 2.5100301e+19
A29: 45933.708 | B29: 3604 | C29: =IFERROR(VLOOKUP(B29,[1]電話端末!$A$2:$E$284,2,FALSE),"不在") -> 【福岡】奥薗美和 | D29: 3600 | E29: =IFERROR(VLOOKUP(D29,[1]電話端末!$A$2:$E$284,2,FALSE),"不在") -> 【福岡】松尾明日香 | F29: 3600 | G29: =IFERROR(VLOOKUP(F29,[1]電話端末!$A$2:$D$284,2,FALSE),"不在") -> 【福岡】松尾明日香 | H29: 77 | I29: 76 | K29: 2.5100301e+19
A30: 45933.708 | B30: 3352 | C30: =IFERROR(VLOOKUP(B30,[1]電話端末!$A$2:$E$284,2,FALSE),"不在") -> 【名古屋】大渕温子 | D30: 3350 | E30: =IFERROR(VLOOKUP(D30,[1]電話端末!$A$2:$E$284,2,FALSE),"不在") -> 【名古屋】稲垣みちる | F30: 3350 | G30: =IFERROR(VLOOKUP(F30,[1]電話端末!$A$2:$D$284,2,FALSE),"不在") -> 【名古屋】稲垣みちる | H30: 25 | I30: 24 | K30: 2.5100301e+19
A31: 45933.708 | B31: 3008 | C31: =IFERROR(VLOOKUP(B31,[1]電話端末!$A$2:$E$284,2,FALSE),"不在") -> 【東京】片桐芳夫 | D31: 3103 | E31: =IFERROR(VLOOKUP(D31,[1]電話端末!$A$2:$E$284,2,FALSE),"不在") -> 【横浜】舞智江 | F31: 3103 | G31: =IFERROR(VLOOKUP(F31,[1]電話端末!$A$2:$D$284,2,FALSE),"不在") -> 【横浜】舞智江 | H31: 20 | I31: 18 | K31: 2.5100301e+19
A32: 45933.701 | B32: 3600 | C32: =IFERROR(VLOOKUP(B32,[1]電話端末!$A$2:$E$284,2,FALSE),"不在") -> 【福岡】松尾明日香 | D32: 3601 | E32: =IFERROR(VLOOKUP(D32,[1]電話端末!$A$2:$E$284,2,FALSE),"不在") -> 【福岡】松添愛 | F32: 3601 | G32: =IFERROR(VLOOKUP(F32,[1]電話端末!$A$2:$D$284,2,FALSE),"不在") -> 【福岡】松添愛 | H32: 43 | I32: 40 | K32: 2.5100301e+19
A33: 45933.7 | B33: 3000 | C33: =IFERROR(VLOOKUP(B33,[1]電話端末!$A$2:$E$284,2,FALSE),"不在") -> 【東京】西垣彩 | D33: 3300 | E33: =IFERROR(VLOOKUP(D33,[1]電話端末!$A$2:$E$284,2,FALSE),"不在") -> 【千葉】小島佳菜 | G33: =IFERROR(VLOOKUP(F33,[1]電話端末!$A$2:$D$284,2,FALSE),"不在") -> 不在 | H33: 15 | I33: 0 | K33: 2.5100301e+19
A34: 45933.698 | B34: 3000 | C34: =IFERROR(VLOOKUP(B34,[1]電話端末!$A$2:$E$284,2,FALSE),"不在") -> 【東京】西垣彩 | D34: 5000 | E34: =IFERROR(VLOOKUP(D34,[1]電話端末!$A$2:$E$284,2,FALSE),"不在") -> 【千葉】着信グループ | F34: 3152 | G34: =IFERROR(VLOOKUP(F34,[1]電話端末!$A$2:$D$284,2,FALSE),"不在") -> 【埼玉】細田昌子 | H34: 22 | I34: 14 | K34: 2.5100301e+19
A35: 45933.698 | B35: 3000 | C35: =IFERROR(VLOOKUP(B35,[1]電話端末!$A$2:$E$284,2,FALSE),"不在") -> 【東京】西垣彩 | D35: 3300 | E35: =IFERROR(VLOOKUP(D35,[1]電話端末!$A$2:$E$284,2,FALSE),"不在") -> 【千葉】小島佳菜 | G35: =IFERROR(VLOOKUP(F35,[1]電話端末!$A$2:$D$284,2,FALSE),"不在") -> 不在 | H35: 15 | I35: 0 | K35: 2.5100301e+19
A36: 45933.697 | B36: 3751 | C36: =IFERROR(VLOOKUP(B36,[1]電話端末!$A$2:$E$284,2,FALSE),"不在") -> 【流山】鴻池千紗都 | D36: 1010 | E36: =IFERROR(VLOOKUP(D36,[1]電話端末!$A$2:$E$284,2,FALSE),"不在") -> 【流山】浅沼潤也 | G36: =IFERROR(VLOOKUP(F36,[1]電話端末!$A$2:$D$284,2,FALSE),"不在") -> 不在 | H36: 32 | I36: 0 | K36: 2.5100301e+19
A37: 45933.697 | B37: 3600 | C37: =IFERROR(VLOOKUP(B37,[1]電話端末!$A$2:$E$284,2,FALSE),"不在") -> 【福岡】松尾明日香 | D37: 3602 | E37: =IFERROR(VLOOKUP(D37,[1]電話端末!$A$2:$E$284,2,FALSE),"不在") -> 【福岡】山崎芹奈 | F37: 3602 | G37: =IFERROR(VLOOKUP(F37,[1]電話端末!$A$2:$D$284,2,FALSE),"不在") -> 【福岡】山崎芹奈 | H37: 43 | I37: 39 | K37: 2.5100301e+19
A38: 45933.694 | B38: 1010 | C38: =IFERROR(VLOOKUP(B38,[1]電話端末!$A$2:$E$284,2,FALSE),"不在") -> 【流山】浅沼潤也 | D38: 3751 | E38: =IFERROR(VLOOKUP(D38,[1]電話端末!$A$2:$E$284,2,FALSE),"不在") -> 【流山】鴻池千紗都 | F38: 3751 | G38: =IFERROR(VLOOKUP(F38,[1]電話端末!$A$2:$D$284,2,FALSE),"不在") -> 【流山】鴻池千紗都 | H38: 54 | I38: 52 | K38: 2.5100301e+19
A39: 45933.694 | B39: 3600 | C39: =IFERROR(VLOOKUP(B39,[1]電話端末!$A$2:$E$284,2,FALSE),"不在") -> 【福岡】松尾明日香 | D39: 1155 | E39: =IFERROR(VLOOKUP(D39,[1]電話端末!$A$2:$E$284,2,FALSE),"不在") -> 【本社経理】池上有花 | F39: 1003 | G39: =IFERROR(VLOOKUP(F39,[1]電話端末!$A$2:$D$284,2,FALSE),"不在") -> 【本社経理】池上有花 | H39: 23 | I39: 20 | K39: 2.5100301e+19
A40: 45933.693 | B40: 3600 | C40: =IFERROR(VLOOKUP(B40,[1]電話端末!$A$2:$E$284,2,FALSE),"不在") -> 【福岡】松尾明日香 | D40: 1155 | E40: =IFERROR(VLOOKUP(D40,[1]電話端末!$A$2:$E$284,2,FALSE),"不在") -> 【本社経理】池上有花 | F40: 1003 | G40: =IFERROR(VLOOKUP(F40,[1]電話端末!$A$2:$D$284,2,FALSE),"不在") -> 【本社経理】池上有花 | H40: 22 | I40: 19 | K40: 2.5100301e+19
A41: 45933.692 | B41: 2004 | C41: =IFERROR(VLOOKUP(B41,[1]電話端末!$A$2:$E$284,2,FALSE),"不在") -> 【MF大阪】西村浩和 | D41: 1141 | E41: =IFERROR(VLOOKUP(D41,[1]電話端末!$A$2:$E$284,2,FALSE),"不在") -> 【本社輸入】細川靖司 | F41: 1141 | G41: =IFERROR(VLOOKUP(F41,[1]電話端末!$A$2:$D$284,2,FALSE),"不在") -> 【本社輸入】細川靖司 | H41: 506 | I41: 498 | K41: 2.5100301e+19
A42: 45933.691 | B42: 1010 | C42: =IFERROR(VLOOKUP(B42,[1]電話端末!$A$2:$E$284,2,FALSE),"不在") -> 【流山】浅沼潤也 | D42: 3751 | E42: =IFERROR(VLOOKUP(D42,[1]電話端末!$A$2:$E$284,2,FALSE),"不在") -> 【流山】鴻池千紗都 | G42: =IFERROR(VLOOKUP(F42,[1]電話端末!$A$2:$D$284,2,FALSE),"不在") -> 不在 | H42: 0 | I42: 0 | K42: 2.5100301e+19
A43: 45933.691 | B43: 3508 | C43: =IFERROR(VLOOKUP(B43,[1]電話端末!$A$2:$E$284,2,FALSE),"不在") -> 【岡山】岸本麻衣子 | D43: 05423 | E43: =IFERROR(VLOOKUP(D43,[1]電話端末!$A$2:$E$284,2,FALSE),"不在") -> 不在 | G43: =IFERROR(VLOOKUP(F43,[1]電話端末!$A$2:$D$284,2,FALSE),"不在") -> 不在 | H43: 0 | I43: 0 | K43: 2.5100301e+19
A44: 45933.691 | B44: 3751 | C44: =IFERROR(VLOOKUP(B44,[1]電話端末!$A$2:$E$284,2,FALSE),"不在") -> 【流山】鴻池千紗都 | D44: 5001 | E44: =IFERROR(VLOOKUP(D44,[1]電話端末!$A$2:$E$284,2,FALSE),"不在") -> 【東京】着信グループ | F44: 3001 | G44: =IFERROR(VLOOKUP(F44,[1]電話端末!$A$2:$D$284,2,FALSE),"不在") -> 【東京】高澤早紀 | H44: 48 | I44: 46 | K44: 2.5100301e+19
A45: 45933.69 | B45: 3111 | C45: =IFERROR(VLOOKUP(B45,[1]電話端末!$A$2:$E$284,2,FALSE),"不在") -> 【横浜】横内敦 | D45: 3054 | E45: =IFERROR(VLOOKUP(D45,[1]電話端末!$A$2:$E$284,2,FALSE),"不在") -> 【本社総務】吉田亜依 | F45: 3054 | G45: =IFERROR(VLOOKUP(F45,[1]電話端末!$A$2:$D$284,2,FALSE),"不在") -> 【本社総務】吉田亜依 | H45: 72 | I45: 68 | K45: 2.5100301e+19
A46: 45933.688 | B46: 3502 | C46: =IFERROR(VLOOKUP(B46,[1]電話端末!$A$2:$E$284,2,FALSE),"不在") -> 【岡山】伊藤優 | D46: 3151 | E46: =IFERROR(VLOOKUP(D46,[1]電話端末!$A$2:$E$284,2,FALSE),"不在") -> 【埼玉】池田千恵子 | F46: 3151 | G46: =IFERROR(VLOOKUP(F46,[1]電話端末!$A$2:$D$284,2,FALSE),"不在") -> 【埼玉】池田千恵子 | H46: 50 | I46: 48 | K46: 2.5100301e+19
A47: 45933.687 | B47: 3603 | C47: =IFERROR(VLOOKUP(B47,[1]電話端末!$A$2:$E$284,2,FALSE),"不在") -> 【福岡】重松宝成 | D47: 3600 | E47: =IFERROR(VLOOKUP(D47,[1]電話端末!$A$2:$E$284,2,FALSE),"不在") -> 【福岡】松尾明日香 | F47: 3600 | G47: =IFERROR(VLOOKUP(F47,[1]電話端末!$A$2:$D$284,2,FALSE),"不在") -> 【福岡】松尾明日香 | H47: 78 | I47: 77 | K47: 2.5100301e+19
A48: 45933.685 | B48: 3002 | C48: =IFERROR(VLOOKUP(B48,[1]電話端末!$A$2:$E$284,2,FALSE),"不在") -> 【東京】佐々木美咲 | D48: 3902 | E48: =IFERROR(VLOOKUP(D48,[1]電話端末!$A$2:$E$284,2,FALSE),"不在") -> 【多摩】高久啓汰 | G48: =IFERROR(VLOOKUP(F48,[1]電話端末!$A$2:$D$284,2,FALSE),"不在") -> 不在 | H48: 6 | I48: 0 | K48: 2.5100301e+19
...
