Workbook
Name ExternalData_1: 外線着信!$A$1:$BF$6738
Name ExternalData_1: 外線発信!$A$1:$AG$5501
Name ExternalData_1: 内線通話!$A$1:$CE$1525
Name ExternalData_10: 外線着信!$A$41138:$BF$45738
Name ExternalData_10: 外線発信!$A$32843:$AG$36604
Name ExternalData_10: 内線通話!$A$8411:$CE$9391
Name ExternalData_11: 外線着信!$A$1:$BD$6738
Name ExternalData_11: 外線発信!$A$1:$AF$5501
Name ExternalData_11: 内線通話!$A$1:$CB$1525
Name ExternalData_12: 外線着信!$A$1:$BB$4602
Name ExternalData_12: 外線発信!$A$1:$AE$3763
Name ExternalData_12: 内線通話!$A$1:$BY$982
Name ExternalData_13: 外線着信!$A$1:$AZ$3920
Name ExternalData_13: 外線発信!$A$1:$AD$3191
Name ExternalData_13: 内線通話!$A$1:$BV$848
Name ExternalData_14: 外線着信!$A$1:$AX$4481
Name ExternalData_14: 外線発信!$A$1:$AC$3509
Name ExternalData_14: 内線通話!$A$1:$BS$862
Name ExternalData_15: 外線着信!$A$1:$AV$6691
Name ExternalData_15: 外線発信!$A$1:$AB$5411
Name ExternalData_15: 内線通話!$A$1:$BP$1425
Name ExternalData_16: 外線着信!$A$1:$AT$24
Name ExternalData_16: 外線発信!$A$1:$AA$1
Name ExternalData_16: 内線通話!$A$1:$BM$1
Name ExternalData_17: 外線着信!$A$1:$AR$7143
Name ExternalData_17: 外線発信!$A$1:$Z$5752
Name ExternalData_17: 内線通話!$A$1:$BJ$1479
Name ExternalData_18: 外線着信!$A$1:$AP$2415
Name ExternalData_18: 外線発信!$A$1:$Y$1795
Name ExternalData_18: 内線通話!$A$1:$BG$485
Name ExternalData_19: 外線着信!$A$1:$AN$4798
Name ExternalData_19: 外線発信!$A$1:$X$3919
Name ExternalData_19: 内線通話!$A$1:$BD$940
Name ExternalData_2: 外線着信!$A$6739:$BF$10657
Name ExternalData_2: 外線発信!$A$5502:$AG$8691
Name ExternalData_2: 内線通話!$A$1526:$CE$2372
Name ExternalData_20: 外線着信!$A$1:$AL$4935
Name ExternalData_20: 外線発信!$A$1:$W$3771
Name ExternalData_20: 内線通話!$A$1:$BA$853
Name ExternalData_21: 外線着信!$A$1:$AJ$6738
Name ExternalData_21: 外線発信!$A$1:$V$5501
Name ExternalData_21: 内線通話!$A$1:$AX$1525
Name ExternalData_22: 外線着信!$A$1:$AH$3920
Name ExternalData_22: 外線発信!$A$1:$U$3191
Name ExternalData_22: 内線通話!$A$1:$AU$848
Name ExternalData_23: 外線着信!$A$1:$AF$4481
Name ExternalData_23: 外線発信!$A$1:$T$3509
Name ExternalData_23: 内線通話!$A$1:$AR$862
Name ExternalData_24: 外線着信!$A$1:$AD$6691
Name ExternalData_24: 外線発信!$A$1:$S$5411
Name ExternalData_24: 内線通話!$A$1:$AO$1425
Name ExternalData_25: 外線着信!$A$1:$AB$24
Name ExternalData_25: 外線発信!$A$1:$R$1
Name ExternalData_25: 内線通話!$A$1:$AL$1
Name ExternalData_26: 外線着信!$A$1:$Z$7143
Name ExternalData_26: 外線発信!$A$1:$Q$5752
Name ExternalData_26: 内線通話!$A$1:$AI$1479
Name ExternalData_27: 外線着信!$A$1:$X$2415
Name ExternalData_27: 外線発信!$A$1:$P$1795
Name ExternalData_27: 内線通話!$A$1:$AF$485

Sheet 着信件数
A1: 拠点 | B1: 内線 | D1: 外線 | F1: 他拠点へ転送 | G1: 他拠点から転送
B2: 入電 | C2: 着電 | D2: 入電 | E2: 着電 | P2: 発着信履歴_20251010-20251012
A3: 東京 | B3: =COUNTIF(内線通話!$E$2:INDEX(内線通話!$E:$E, COUNTA(内線通話!$E:$E)), "【"&A3&"*") -> 24 | C3: =COUNTIF(内線通話!$G$2:INDEX(内線通話!$G:$G, COUNTA(内線通話!$G:$G)), "【"&A3&"*") -> 21 | D3: =COUNTIF(外線着信!$D$2:INDEX(外線着信!$D:$D, COUNTA(外線着信!$D:$D)), "【"&A3&"*") -> 331 | E3: =COUNTIF(外線着信!$F$2:INDEX(外線着信!$F:$F, COUNTA(外線着信!$F:$F)), "【"&A3&"*") -> 323 | G3: 流山
A4: 横浜 | B4: =COUNTIF(内線通話!$E$2:INDEX(内線通話!$E:$E, COUNTA(内線通話!$E:$E)), "【"&A4&"*") -> 34 | C4: =COUNTIF(内線通話!$G$2:INDEX(内線通話!$G:$G, COUNTA(内線通話!$G:$G)), "【"&A4&"*") -> 25 | D4: =COUNTIF(外線着信!$D$2:INDEX(外線着信!$D:$D, COUNTA(外線着信!$D:$D)), "【"&A4&"*") -> 389 | E4: =COUNTIF(外線着信!$F$2:INDEX(外線着信!$F:$F, COUNTA(外線着信!$F:$F)), "【"&A4&"*") -> 382 | G4: 多摩
A5: 埼玉 | B5: =COUNTIF(内線通話!$E$2:INDEX(内線通話!$E:$E, COUNTA(内線通話!$E:$E)), "【"&A5&"*") -> 32 | C5: =COUNTIF(内線通話!$G$2:INDEX(内線通話!$G:$G, COUNTA(内線通話!$G:$G)), "【"&A5&"*") -> 25 | D5: =COUNTIF(外線着信!$D$2:INDEX(外線着信!$D:$D, COUNTA(外線着信!$D:$D)), "【"&A5&"*") -> 300 | E5: =COUNTIF(外線着信!$F$2:INDEX(外線着信!$F:$F, COUNTA(外線着信!$F:$F)), "【"&A5&"*") -> 312 | G5: 千葉・北関東 | J5: 入電：電話が入った件数
A6: 滋賀 | B6: =COUNTIF(内線通話!$E$2:INDEX(内線通話!$E:$E, COUNTA(内線通話!$E:$E)), "【"&A6&"*") -> 5 | C6: =COUNTIF(内線通話!$G$2:INDEX(内線通話!$G:$G, COUNTA(内線通話!$G:$G)), "【"&A6&"*") -> 3 | D6: =COUNTIF(外線着信!$D$2:INDEX(外線着信!$D:$D, COUNTA(外線着信!$D:$D)), "【"&A6&"*") -> 102 | E6: =COUNTIF(外線着信!$F$2:INDEX(外線着信!$F:$F, COUNTA(外線着信!$F:$F)), "【"&A6&"*") -> 108 | G6: 金沢 | J6: 着電：電話を取った件数
A7: 大阪 | B7: =COUNTIF(内線通話!$E$2:INDEX(内線通話!$E:$E, COUNTA(内線通話!$E:$E)), "【"&A7&"*") -> 15 | C7: =COUNTIF(内線通話!$G$2:INDEX(内線通話!$G:$G, COUNTA(内線通話!$G:$G)), "【"&A7&"*") -> 15 | D7: =COUNTIF(外線着信!$D$2:INDEX(外線着信!$D:$D, COUNTA(外線着信!$D:$D)), "【"&A7&"*") -> 60 | E7: =COUNTIF(外線着信!$F$2:INDEX(外線着信!$F:$F, COUNTA(外線着信!$F:$F)), "【"&A7&"*") -> 11 | F7: 岡山
A8: 千葉 | B8: =COUNTIF(内線通話!$E$2:INDEX(内線通話!$E:$E, COUNTA(内線通話!$E:$E)), "【"&A8&"*") -> 18 | C8: =COUNTIF(内線通話!$G$2:INDEX(内線通話!$G:$G, COUNTA(内線通話!$G:$G)), "【"&A8&"*") -> 11 | D8: =COUNTIF(外線着信!$D$2:INDEX(外線着信!$D:$D, COUNTA(外線着信!$D:$D)), "【"&A8&"*") -> 109 | E8: =COUNTIF(外線着信!$F$2:INDEX(外線着信!$F:$F, COUNTA(外線着信!$F:$F)), "【"&A8&"*") -> 67 | F8: 埼玉
A9: 福岡 | B9: =COUNTIF(内線通話!$E$2:INDEX(内線通話!$E:$E, COUNTA(内線通話!$E:$E)), "【"&A9&"*") -> 75 | C9: =COUNTIF(内線通話!$G$2:INDEX(内線通話!$G:$G, COUNTA(内線通話!$G:$G)), "【"&A9&"*") -> 65 | D9: =COUNTIF(外線着信!$D$2:INDEX(外線着信!$D:$D, COUNTA(外線着信!$D:$D)), "【"&A9&"*") -> 196 | E9: =COUNTIF(外線着信!$F$2:INDEX(外線着信!$F:$F, COUNTA(外線着信!$F:$F)), "【"&A9&"*") -> 184 | G9: 広島・熊本
A10: 岡山 | B10: =COUNTIF(内線通話!$E$2:INDEX(内線通話!$E:$E, COUNTA(内線通話!$E:$E)), "【"&A10&"*") -> 16 | C10: =COUNTIF(内線通話!$G$2:INDEX(内線通話!$G:$G, COUNTA(内線通話!$G:$G)), "【"&A10&"*") -> 13 | D10: =COUNTIF(外線着信!$D$2:INDEX(外線着信!$D:$D, COUNTA(外線着信!$D:$D)), "【"&A10&"*") -> 174 | E10: =COUNTIF(外線着信!$F$2:INDEX(外線着信!$F:$F, COUNTA(外線着信!$F:$F)), "【"&A10&"*") -> 227 | G10: 大阪・静岡
A11: 名古屋 | B11: =COUNTIF(内線通話!$E$2:INDEX(内線通話!$E:$E, COUNTA(内線通話!$E:$E)), "【"&A11&"*") -> 36 | C11: =COUNTIF(内線通話!$G$2:INDEX(内線通話!$G:$G, COUNTA(内線通話!$G:$G)), "【"&A11&"*") -> 36 | D11: =COUNTIF(外線着信!$D$2:INDEX(外線着信!$D:$D, COUNTA(外線着信!$D:$D)), "【"&A11&"*") -> 113 | E11: =COUNTIF(外線着信!$F$2:INDEX(外線着信!$F:$F, COUNTA(外線着信!$F:$F)), "【"&A11&"*") -> 105
A12: 仙台 | B12: =COUNTIF(内線通話!$E$2:INDEX(内線通話!$E:$E, COUNTA(内線通話!$E:$E)), "【"&A12&"*") -> 15 | C12: =COUNTIF(内線通話!$G$2:INDEX(内線通話!$G:$G, COUNTA(内線通話!$G:$G)), "【"&A12&"*") -> 14 | D12: =COUNTIF(外線着信!$D$2:INDEX(外線着信!$D:$D, COUNTA(外線着信!$D:$D)), "【"&A12&"*") -> 297 | E12: =COUNTIF(外線着信!$F$2:INDEX(外線着信!$F:$F, COUNTA(外線着信!$F:$F)), "【"&A12&"*") -> 311 | G12: 札幌
A13: 広島 | B13: =COUNTIF(内線通話!$E$2:INDEX(内線通話!$E:$E, COUNTA(内線通話!$E:$E)), "【"&A13&"*") -> 4 | C13: =COUNTIF(内線通話!$G$2:INDEX(内線通話!$G:$G, COUNTA(内線通話!$G:$G)), "【"&A13&"*") -> 4 | D13: =COUNTIF(外線着信!$D$2:INDEX(外線着信!$D:$D, COUNTA(外線着信!$D:$D)), "【"&A13&"*") -> 5 | E13: =COUNTIF(外線着信!$F$2:INDEX(外線着信!$F:$F, COUNTA(外線着信!$F:$F)), "【"&A13&"*") -> 0 | F13: 福岡
A14: 札幌 | B14: =COUNTIF(内線通話!$E$2:INDEX(内線通話!$E:$E, COUNTA(内線通話!$E:$E)), "【"&A14&"*") -> 3 | C14: =COUNTIF(内線通話!$G$2:INDEX(内線通話!$G:$G, COUNTA(内線通話!$G:$G)), "【"&A14&"*") -> 0 | D14: =COUNTIF(外線着信!$D$2:INDEX(外線着信!$D:$D, COUNTA(外線着信!$D:$D)), "【"&A14&"*") -> 34 | E14: =COUNTIF(外線着信!$F$2:INDEX(外線着信!$F:$F, COUNTA(外線着信!$F:$F)), "【"&A14&"*") -> 2 | F14: 仙台
A15: 静岡 | B15: =COUNTIF(内線通話!$E$2:INDEX(内線通話!$E:$E, COUNTA(内線通話!$E:$E)), "【"&A15&"*") -> 0 | C15: =COUNTIF(内線通話!$G$2:INDEX(内線通話!$G:$G, COUNTA(内線通話!$G:$G)), "【"&A15&"*") -> 0 | D15: =COUNTIF(外線着信!$D$2:INDEX(外線着信!$D:$D, COUNTA(外線着信!$D:$D)), "【"&A15&"*") -> 26 | E15: =COUNTIF(外線着信!$F$2:INDEX(外線着信!$F:$F, COUNTA(外線着信!$F:$F)), "【"&A15&"*") -> 0 | F15: 岡山
A16: 北関東 | B16: =COUNTIF(内線通話!$E$2:INDEX(内線通話!$E:$E, COUNTA(内線通話!$E:$E)), "【"&A16&"*") -> 0 | C16: =COUNTIF(内線通話!$G$2:INDEX(内線通話!$G:$G, COUNTA(内線通話!$G:$G)), "【"&A16&"*") -> 0 | D16: =COUNTIF(外線着信!$D$2:INDEX(外線着信!$D:$D, COUNTA(外線着信!$D:$D)), "【"&A16&"*") -> 12 | E16: =COUNTIF(外線着信!$F$2:INDEX(外線着信!$F:$F, COUNTA(外線着信!$F:$F)), "【"&A16&"*") -> 0 | F16: 埼玉
A17: 多摩 | B17: =COUNTIF(内線通話!$E$2:INDEX(内線通話!$E:$E, COUNTA(内線通話!$E:$E)), "【"&A17&"*") -> 6 | C17: =COUNTIF(内線通話!$G$2:INDEX(内線通話!$G:$G, COUNTA(内線通話!$G:$G)), "【"&A17&"*") -> 4 | D17: =COUNTIF(外線着信!$D$2:INDEX(外線着信!$D:$D, COUNTA(外線着信!$D:$D)), "【"&A17&"*") -> 23 | E17: =COUNTIF(外線着信!$F$2:INDEX(外線着信!$F:$F, COUNTA(外線着信!$F:$F)), "【"&A17&"*") -> 8 | F17: 横浜
A18: 流山 | B18: =COUNTIF(内線通話!$E$2:INDEX(内線通話!$E:$E, COUNTA(内線通話!$E:$E)), "【"&A18&"*") -> 52 | C18: =COUNTIF(内線通話!$G$2:INDEX(内線通話!$G:$G, COUNTA(内線通話!$G:$G)), "【"&A18&"*") -> 35 | D18: =COUNTIF(外線着信!$D$2:INDEX(外線着信!$D:$D, COUNTA(外線着信!$D:$D)), "【"&A18&"*") -> 47 | E18: =COUNTIF(外線着信!$F$2:INDEX(外線着信!$F:$F, COUNTA(外線着信!$F:$F)), "【"&A18&"*") -> 44 | F18: 東京
A19: 熊本 | B19: =COUNTIF(内線通話!$E$2:INDEX(内線通話!$E:$E, COUNTA(内線通話!$E:$E)), "【"&A19&"*") -> 0 | C19: =COUNTIF(内線通話!$G$2:INDEX(内線通話!$G:$G, COUNTA(内線通話!$G:$G)), "【"&A19&"*") -> 0 | D19: =COUNTIF(外線着信!$D$2:INDEX(外線着信!$D:$D, COUNTA(外線着信!$D:$D)), "【"&A19&"*") -> 0 | E19: =COUNTIF(外線着信!$F$2:INDEX(外線着信!$F:$F, COUNTA(外線着信!$F:$F)), "【"&A19&"*") -> 0 | F19: 福岡
A20: 金沢 | B20: =COUNTIF(内線通話!$E$2:INDEX(内線通話!$E:$E, COUNTA(内線通話!$E:$E)), "【"&A20&"*") -> 1 | C20: =COUNTIF(内線通話!$G$2:INDEX(内線通話!$G:$G, COUNTA(内線通話!$G:$G)), "【"&A20&"*") -> 1 | D20: =COUNTIF(外線着信!$D$2:INDEX(外線着信!$D:$D, COUNTA(外線着信!$D:$D)), "【"&A20&"*") -> 15 | E20: =COUNTIF(外線着信!$F$2:INDEX(外線着信!$F:$F, COUNTA(外線着信!$F:$F)), "【"&A20&"*") -> 0 | F20: 滋賀
A21: 本社 | B21: =COUNTIF(内線通話!$E$2:INDEX(内線通話!$E:$E, COUNTA(内線通話!$E:$E)), "【"&A21&"*") -> 66 | C21: =COUNTIF(内線通話!$G$2:INDEX(内線通話!$G:$G, COUNTA(内線通話!$G:$G)), "【"&A21&"*") -> 48 | D21: =COUNTIF(外線着信!$D$2:INDEX(外線着信!$D:$D, COUNTA(外線着信!$D:$D)), "【"&A21&"*") -> 57 | E21: =COUNTIF(外線着信!$F$2:INDEX(外線着信!$F:$F, COUNTA(外線着信!$F:$F)), "【"&A21&"*") -> 48
A22: MF大阪 | B22: =COUNTIF(内線通話!$E$2:INDEX(内線通話!$E:$E, COUNTA(内線通話!$E:$E)), "【"&A22&"*") -> 28 | C22: =COUNTIF(内線通話!$G$2:INDEX(内線通話!$G:$G, COUNTA(内線通話!$G:$G)), "【"&A22&"*") -> 19 | D22: =COUNTIF(外線着信!$D$2:INDEX(外線着信!$D:$D, COUNTA(外線着信!$D:$D)), "【"&A22&"*") -> 105 | E22: =COUNTIF(外線着信!$F$2:INDEX(外線着信!$F:$F, COUNTA(外線着信!$F:$F)), "【"&A22&"*") -> 104
A23: MF東京 | B23: =COUNTIF(内線通話!$E$2:INDEX(内線通話!$E:$E, COUNTA(内線通話!$E:$E)), "【"&A23&"*") -> 13 | C23: =COUNTIF(内線通話!$G$2:INDEX(内線通話!$G:$G, COUNTA(内線通話!$G:$G)), "【"&A23&"*") -> 11 | D23: =COUNTIF(外線着信!$D$2:INDEX(外線着信!$D:$D, COUNTA(外線着信!$D:$D)), "【"&A23&"*") -> 53 | E23: =COUNTIF(外線着信!$F$2:INDEX(外線着信!$F:$F, COUNTA(外線着信!$F:$F)), "【"&A23&"*") -> 49

Sheet 電話端末
A1: 内線番号 | B1: 端末名 | C1: 端末種別 | D1: メモ | E1: 作成日時
A2: 1002 | B2: 【本社経理】羽鳥由美 | C2: SAXA | E2: 2025/01/08 14:34:21
A3: 1003 | B3: 【本社経理】池上有花 | C3: SAXA | E3: 2025/01/07 14:37:16
A4: 1010 | B4: 【流山】浅沼潤也 | C4: BIZTELソフトフォン | D4: 浅沼潤也(内線のみ) | E4: 2025/01/27 13:46:35
A5: 1013 | B5: 【千葉】遠藤和行 | C5: BIZTELソフトフォン | D5: ソフトフォン継続利用(固定電話機も設置) | E5: 2021/04/23 15:00:00
A6: 1014 | B6: 【千葉】平野翔大 | C6: BIZTELソフトフォン | D6: ソフトフォン継続利用(固定電話機も設置) | E6: 2025/03/04 15:02:01
A7: 1023 | B7: 【千葉】吉川博之 | C7: BIZTELソフトフォン | D7: ソフトフォンのみ使用 | E7: 2023/09/27 13:36:20
A8: 1024 | B8: 【千葉】小島佳奈 | C8: BIZTELソフトフォン | D8: 固定電話機と併用 | E8: 2024/03/22 10:31:16
A9: 1050 | B9: 【本社】受付用電話機 | C9: その他IPフォン（rfc2833) | E9: 2022/12/07 11:28:08
A10: 1120 | B10: 【本社EC】別府菜々美 | C10: BIZTELソフトフォン | D10: ソフトフォンのみ使用 | E10: 2025/03/27 15:43:29
A11: 1121 | B11: 【本社EC】山口莉奈 | C11: BIZTELソフトフォン | D11: ソフトフォンのみ使用 | E11: 2024/09/20 14:03:04
A12: 1122 | B12: 【本社IT】松本郷 | C12: BIZTELソフトフォン | D12: ソフトフォンのみ使用 | E12: 2022/12/14 15:40:44
A13: 1123 | B13: 【本社IT】梶ヶ谷知晃 | C13: BIZTELソフトフォン | D13: ソフトフォンのみ使用 | E13: 2023/08/29 13:57:03
A14: 1124 | B14: 【本社IT】大坪航介 | C14: BIZTELソフトフォン | D14: ソフトフォンのみ使用 | E14: 2023/01/05 11:52:29
A15: 1130 | B15: 【本社EC】EC外線 | C15: BIZTELソフトフォン | D15: 【本社EC】EC外線 | E15: 2023/01/24 15:43:15
A16: 1132 | B16: 【本社EC】鈴木浩允 | C16: BIZTELソフトフォン | D16: ソフトフォンのみ使用 | E16: 2023/01/26 17:14:29
A17: 1133 | B17: 【本社EC】印藤躍 | C17: BIZTELソフトフォン | D17: ソフトフォンのみ使用 | E17: 2024/05/02 11:13:26
A18: 1134 | B18: 【本社EC】大城明日香 | C18: BIZTELソフトフォン | D18: ソフトフォンのみ使用 | E18: 2023/11/22 17:00:03
A19: 1135 | B19: 【本社IT】福原弘明 | C19: BIZTELソフトフォン | D19: ソフトフォンのみ使用 | E19: 2023/01/26 17:16:28
A20: 1136 | B20: 【本社EC】渡辺慶太 | C20: BIZTELソフトフォン | D20: ソフトフォンのみ使用 | E20: 2024/02/29 14:18:46
A21: 1137 | B21: 【本社EC】猶貞彩 | C21: BIZTELソフトフォン | D21: ソフトフォンのみ使用 | E21: 2023/01/26 17:17:31
... A32: 1155 | B32: 【本社経理】池上有花 | C32: BIZTELソフトフォン | D32: ソフトフォンのみ使用 | E32: 2023/12/22 14:21:07
A33: 1200 | B33: 【MF大阪】大村達也 | C33: BIZTELソフトフォン | E33: 2025/03/03 12:12:55
A34: 1501 | B34: 【岡山】山崎修二 | C34: BIZTELソフトフォン | D34: ソフトフォン | E34: 2025/04/15 12:34:38
A35: 1502 | B35: 【岡山】桐野敏行 | C35: BIZTELソフトフォン | D35: ソフトフォン | E35: 2025/04/15 12:35:30
A36: 1503 | B36: 【岡山】矢野夏絵 | C36: BIZTELソフトフォン | D36: ソフトフォン継続利用(固定電話機も設置) | E36: 2023/03/02 14:55:44
A37: 1504 | B37: 【岡山】岩佐寛子 | C37: BIZTELソフトフォン | D37: ソフトフォン継続利用(固定電話機も設置) | E37: 2023/03/02 14:55:44
A38: 1506 | B38: 【岡山】伊藤優 | C38: BIZTELソフトフォン | D38: ソフトフォン継続利用(固定電話機も設置) | E38: 2023/03/02 14:55:44
A39: 1507 | B39: 【岡山】北添恵 | C39: BIZTELソフトフォン | D39: ソフトフォン継続利用(固定電話機も設置) | E39: 2023/03/02 14:55:44
A40: 1508 | B40: 【岡山】武政彩果 | C40: BIZTELソフトフォン | D40: ソフトフォン継続利用(固定電話機も設置) | E40: 2023/03/02 14:55:44
A41: 2000 | B41: 【MF大阪】受付電話 | C41: その他IPフォン（rfc2833) | E41: 2024/12/04 16:04:03
A42: 2001 | B42: 【MF大阪】高橋雅樹 | C42: SAXA | E42: 2024/12/03 19:10:09
A43: 2002 | B43: 【MF大阪】西村公宏 | C43: SAXA | E43: 2024/12/03 19:10:10
A44: 2003 | B44: 【MF大阪】高村一美 | C44: SAXA | E44: 2024/12/03 19:10:09
A45: 2004 | B45: 【MF大阪】西村浩和 | C45: SAXA | E45: 2024/12/03 19:10:10
A46: 2005 | B46: 【MF大阪】多田哲平 | C46: SAXA | E46: 2024/12/03 19:10:09
A47: 2006 | B47: 【MF大阪】吉田亮 | C47: SAXA | E47: 2024/12/03 19:11:15
A48: 2007 | B48: 【MF大阪】高龍大 | C48: SAXA | E48: 2024/12/03 19:10:08
A49: 2008 | B49: 【MF大阪】松尾一誠 | C49: SAXA | E49: 2024/12/03 19:11:14
A50: 2009 | B50: 【MF大阪】橋本雅 | C50: SAXA | E50: 2024/12/03 19:10:11
...

Sheet 内線通話
A1: 時刻 | B1: 発信番号 | C1: 発信者 | D1: 着信番号 | E1: 着信者 | F1: 最終着信番号 | G1: 最終着信者 | H1: 通話時間（応答までの時間を含む） | I1: 通話時間 | J1: メモ | K1: リクエストID
A2: 45940.8 | B2: 1132 | C2: =IFERROR(VLOOKUP(B2,電話端末!$A$2:$E$284,2,FALSE),"不在") -> 【本社EC】鈴木浩允 | D2: 2025 | E2: =IFERROR(VLOOKUP(D2,電話端末!$A$2:$E$284,2,FALSE),"不在") -> 【MF大阪】後垣幸恵 | F2: 2025 | G2: =IFERROR(VLOOKUP(F2,電話端末!$A$2:$D$284,2,FALSE),"不在") -> 【MF大阪】後垣幸恵 | H2: 108 | I2: 106 | K2: 2.5101001e+19
A3: 45940.797 | B3: 2100 | C3: =IFERROR(VLOOKUP(B3,電話端末!$A$2:$E$284,2,FALSE),"不在") -> 【MF東京】大月紀史 | D3: 2013 | E3: =IFERROR(VLOOKUP(D3,電話端末!$A$2:$E$284,2,FALSE),"不在") -> 【MF大阪】牧聡美 | G3: =IFERROR(VLOOKUP(F3,電話端末!$A$2:$D$284,2,FALSE),"不在") -> 不在 | H3: 17 | I3: 0 | K3: 2.5101001e+19
A4: 45940.796 | B4: 2100 | C4: =IFERROR(VLOOKUP(B4,電話端末!$A$2:$E$284,2,FALSE),"不在") -> 【MF東京】大月紀史 | D4: 2016 | E4: =IFERROR(VLOOKUP(D4,電話端末!$A$2:$E$284,2,FALSE),"不在") -> 【MF大阪】濱尾香 | G4: =IFERROR(VLOOKUP(F4,電話端末!$A$2:$D$284,2,FALSE),"不在") -> 不在 | H4: 17 | I4: 0 | K4: 2.5101001e+19
A5: 45940.768 | B5: 2100 | C5: =IFERROR(VLOOKUP(B5,電話端末!$A$2:$E$284,2,FALSE),"不在") -> 【MF東京】大月紀史 | D5: 2001 | E5: =IFERROR(VLOOKUP(D5,電話端末!$A$2:$E$284,2,FALSE),"不在") -> 【MF大阪】高橋雅樹 | G5: =IFERROR(VLOOKUP(F5,電話端末!$A$2:$D$284,2,FALSE),"不在") -> 不在 | H5: 12 | I5: 0 | K5: 2.5101001e+19
A6: 45940.762 | B6: 2001 | C6: =IFERROR(VLOOKUP(B6,電話端末!$A$2:$E$284,2,FALSE),"不在") -> 【MF大阪】高橋雅樹 | D6: 2109 | E6: =IFERROR(VLOOKUP(D6,電話端末!$A$2:$E$284,2,FALSE),"不在") -> 【MF東京】吉澤拓也 | F6: 2109 | G6: =IFERROR(VLOOKUP(F6,電話端末!$A$2:$D$284,2,FALSE),"不在") -> 【MF東京】吉澤拓也 | H6: 100 | I6: 98 | K6: 2.5101001e+19
A7: 45940.761 | B7: 2001 | C7: =IFERROR(VLOOKUP(B7,電話端末!$A$2:$E$284,2,FALSE),"不在") -> 【MF大阪】高橋雅樹 | D7: 2107 | E7: =IFERROR(VLOOKUP(D7,電話端末!$A$2:$E$284,2,FALSE),"不在") -> 【MF東京】我有一哲 | F7: 2107 | G7: =IFERROR(VLOOKUP(F7,電話端末!$A$2:$D$284,2,FALSE),"不在") -> 【MF東京】我有一哲 | H7: 39 | I7: 34 | K7: 2.5101001e+19
A8: 45940.759 | B8: 2010 | C8: =IFERROR(VLOOKUP(B8,電話端末!$A$2:$E$284,2,FALSE),"不在") -> 【MF大阪】大村達也 | D8: 1136 | E8: =IFERROR(VLOOKUP(D8,電話端末!$A$2:$E$284,2,FALSE),"不在") -> 【本社EC】渡辺慶太 | F8: 1136 | G8: =IFERROR(VLOOKUP(F8,電話端末!$A$2:$D$284,2,FALSE),"不在") -> 【本社EC】渡辺慶太 | H8: 185 | I8: 179 | K8: 2.5101001e+19
A9: 45940.756 | B9: 3059 | C9: =IFERROR(VLOOKUP(B9,電話端末!$A$2:$E$284,2,FALSE),"不在") -> 【本社在庫物流課】黒田靖広 | D9: 2002 | E9: =IFERROR(VLOOKUP(D9,電話端末!$A$2:$E$284,2,FALSE),"不在") -> 【MF大阪】西村公宏 | F9: 2002 | G9: =IFERROR(VLOOKUP(F9,電話端末!$A$2:$D$284,2,FALSE),"不在") -> 【MF大阪】西村公宏 | H9: 95 | I9: 90 | K9: 2.5101001e+19
A10: 45940.754 | B10: 1132 | C10: =IFERROR(VLOOKUP(B10,電話端末!$A$2:$E$284,2,FALSE),"不在") -> 【本社EC】鈴木浩允 | D10: 2010 | E10: =IFERROR(VLOOKUP(D10,電話端末!$A$2:$E$284,2,FALSE),"不在") -> 【MF大阪】大村達也 | F10: 2003 | G10: =IFERROR(VLOOKUP(F10,電話端末!$A$2:$D$284,2,FALSE),"不在") -> 【MF大阪】高村一美 | H10: 372 | I10: 362 | K10: 2.5101001e+19
A11: 45940.753 | B11: 1010 | C11: =IFERROR(VLOOKUP(B11,電話端末!$A$2:$E$284,2,FALSE),"不在") -> 【流山】浅沼潤也 | D11: 3011 | E11: =IFERROR(VLOOKUP(D11,電話端末!$A$2:$E$284,2,FALSE),"不在") -> 【東京】玉川圭介 | F11: 3011 | G11: =IFERROR(VLOOKUP(F11,電話端末!$A$2:$D$284,2,FALSE),"不在") -> 【東京】玉川圭介 | H11: 88 | I11: 69 | K11: 2.5101001e+19
A12: 45940.752 | B12: 3154 | C12: =IFERROR(VLOOKUP(B12,電話端末!$A$2:$E$284,2,FALSE),"不在") -> 【埼玉】竹内梓 | D12: 3500 | E12: =IFERROR(VLOOKUP(D12,電話端末!$A$2:$E$284,2,FALSE),"不在") -> 【岡山】矢野夏絵 | F12: 3500 | G12: =IFERROR(VLOOKUP(F12,電話端末!$A$2:$D$284,2,FALSE),"不在") -> 【岡山】矢野夏絵 | H12: 60 | I12: 57 | K12: 2.5101001e+19
A13: 45940.748 | B13: 3500 | C13: =IFERROR(VLOOKUP(B13,電話端末!$A$2:$E$284,2,FALSE),"不在") -> 【岡山】矢野夏絵 | D13: 5004 | E13: =IFERROR(VLOOKUP(D13,電話端末!$A$2:$E$284,2,FALSE),"不在") -> 【埼玉】着信グループ | F13: 3154 | G13: =IFERROR(VLOOKUP(F13,電話端末!$A$2:$D$284,2,FALSE),"不在") -> 【埼玉】竹内梓 | H13: 167 | I13: 164 | K13: 2.5101001e+19
A14: 45940.747 | B14: 3500 | C14: =IFERROR(VLOOKUP(B14,電話端末!$A$2:$E$284,2,FALSE),"不在") -> 【岡山】矢野夏絵 | D14: 5490 | E14: =IFERROR(VLOOKUP(D14,電話端末!$A$2:$E$284,2,FALSE),"不在") -> 【滋賀】着信グループ | G14: =IFERROR(VLOOKUP(F14,電話端末!$A$2:$D$284,2,FALSE),"不在") -> 不在 | H14: 11 | I14: 0 | K14: 2.5101001e+19
A15: 45940.743 | B15: 1122 | C15: =IFERROR(VLOOKUP(B15,電話端末!$A$2:$E$284,2,FALSE),"不在") -> 【本社IT】松本郷 | D15: 2027 | E15: =IFERROR(VLOOKUP(D15,電話端末!$A$2:$E$284,2,FALSE),"不在") -> 【MF大阪】平山孝潤 | F15: 2027 | G15: =IFERROR(VLOOKUP(F15,電話端末!$A$2:$D$284,2,FALSE),"不在") -> 【MF大阪】平山孝潤 | H15: 169 | I15: 166 | K15: 2.5101001e+19
A16: 45940.742 | B16: 3902 | C16: =IFERROR(VLOOKUP(B16,電話端末!$A$2:$E$284,2,FALSE),"不在") -> 【多摩】高久啓汰 | D16: 3105 | E16: =IFERROR(VLOOKUP(D16,電話端末!$A$2:$E$284,2,FALSE),"不在") -> 【横浜】川崎瞳 | G16: =IFERROR(VLOOKUP(F16,電話端末!$A$2:$D$284,2,FALSE),"不在") -> 不在 | H16: 36 | I16: 0 | K16: 2.5101001e+19
A17: 45940.74 | B17: 3003 | C17: =IFERROR(VLOOKUP(B17,電話端末!$A$2:$E$284,2,FALSE),"不在") -> 【東京】林まど佳 | D17: 2107 | E17: =IFERROR(VLOOKUP(D17,電話端末!$A$2:$E$284,2,FALSE),"不在") -> 【MF東京】我有一哲 | F17: 2107 | G17: =IFERROR(VLOOKUP(F17,電話端末!$A$2:$D$284,2,FALSE),"不在") -> 【MF東京】我有一哲 | H17: 39 | I17: 14 | K17: 2.5101001e+19
A18: 45940.739 | B18: 3551 | C18: =IFERROR(VLOOKUP(B18,電話端末!$A$2:$E$284,2,FALSE),"不在") -> 【広島】小先純平 | D18: 3600 | E18: =IFERROR(VLOOKUP(D18,電話端末!$A$2:$E$284,2,FALSE),"不在") -> 【福岡】松尾明日香 | G18: =IFERROR(VLOOKUP(F18,電話端末!$A$2:$D$284,2,FALSE),"不在") -> 不在 | H18: 11 | I18: 0 | K18: 2.5101001e+19
A19: 45940.739 | B19: 3003 | C19: =IFERROR(VLOOKUP(B19,電話端末!$A$2:$E$284,2,FALSE),"不在") -> 【東京】林まど佳 | D19: 2107 | E19: =IFERROR(VLOOKUP(D19,電話端末!$A$2:$E$284,2,FALSE),"不在") -> 【MF東京】我有一哲 | G19: =IFERROR(VLOOKUP(F19,電話端末!$A$2:$D$284,2,FALSE),"不在") -> 不在 | H19: 23 | I19: 0 | K19: 2.5101001e+19
A20: 45940.739 | B20: 3551 | C20: =IFERROR(VLOOKUP(B20,電話端末!$A$2:$E$284,2,FALSE),"不在") -> 【広島】小先純平 | D20: 3603 | E20: =IFERROR(VLOOKUP(D20,電話端末!$A$2:$E$284,2,FALSE),"不在") -> 【福岡】重松宝成 | G20: =IFERROR(VLOOKUP(F20,電話端末!$A$2:$D$284,2,FALSE),"不在") -> 不在 | H20: 9 | I20: 0 | K20: 2.5101001e+19
A21: 45940.739 | B21: 3450 | C21: =IFERROR(VLOOKUP(B21,電話端末!$A$2:$E$284,2,FALSE),"不在") -> 【大阪】松下愛 | D21: 3501 | E21: =IFERROR(VLOOKUP(D21,電話端末!$A$2:$E$284,2,FALSE),"不在") -> 【岡山】岩佐寛子 | F21: 1504 | G21: =IFERROR(VLOOKUP(F21,電話端末!$A$2:$D$284,2,FALSE),"不在") -> 【岡山】岩佐寛子 | H21: 88 | I21: 83 | K21: 2.5101001e+19
A22: 45940.737 | B22: 2107 | C22: =IFERROR(VLOOKUP(B22,電話端末!$A$2:$E$284,2,FALSE),"不在") -> 【MF東京】我有一哲 | D22: 5001 | E22: =IFERROR(VLOOKUP(D22,電話端末!$A$2:$E$284,2,FALSE),"不在") -> 【東京】着信グループ | F22: 3003 | G22: =IFERROR(VLOOKUP(F22,電話端末!$A$2:$D$284,2,FALSE),"不在") -> 【東京】林まど佳 | H22: 72 | I22: 68 | K22: 2.5101001e+19
A23: 45940.736 | B23: 3551 | C23: =IFERROR(VLOOKUP(B23,電話端末!$A$2:$E$284,2,FALSE),"不在") -> 【広島】小先純平 | D23: 3603 | E23: =IFERROR(VLOOKUP(D23,電話端末!$A$2:$E$284,2,FALSE),"不在") -> 【福岡】重松宝成 | G23: =IFERROR(VLOOKUP(F23,電話端末!$A$2:$D$284,2,FALSE),"不在") -> 不在 | H23: 12 | I23: 0 | K23: 2.5101001e+19
A24: 45940.736 | B24: 1010 | C24: =IFERROR(VLOOKUP(B24,電話端末!$A$2:$E$284,2,FALSE),"不在") -> 【流山】浅沼潤也 | D24: 3752 | E24: =IFERROR(VLOOKUP(D24,電話端末!$A$2:$E$284,2,FALSE),"不在") -> 【流山】石田拓海 | F24: 3752 | G24: =IFERROR(VLOOKUP(F24,電話端末!$A$2:$D$284,2,FALSE),"不在") -> 【流山】石田拓海 | H24: 144 | I24: 142 | K24: 2.5101001e+19
A25: 45940.735 | B25: 3551 | C25: =IFERROR(VLOOKUP(B25,電話端末!$A$2:$E$284,2,FALSE),"不在") -> 【広島】小先純平 | D25: 3603 | E25: =IFERROR(VLOOKUP(D25,電話端末!$A$2:$E$284,2,FALSE),"不在") -> 【福岡】重松宝成 | G25: =IFERROR(VLOOKUP(F25,電話端末!$A$2:$D$284,2,FALSE),"不在") -> 不在 | H25: 14 | I25: 0 | K25: 2.5101001e+19
A26: 45940.733 | B26: 3156 | C26: =IFERROR(VLOOKUP(B26,電話端末!$A$2:$E$284,2,FALSE),"不在") -> 【埼玉】金子友希 | D26: 3352 | E26: =IFERROR(VLOOKUP(D26,電話端末!$A$2:$E$284,2,FALSE),"不在") -> 【名古屋】大渕温子 | F26: 3352 | G26: =IFERROR(VLOOKUP(F26,電話端末!$A$2:$D$284,2,FALSE),"不在") -> 【名古屋】大渕温子 | H26: 36 | I26: 34 | K26: 2.5101001e+19
A27: 45940.733 | B27: 3752 | C27: =IFERROR(VLOOKUP(B27,電話端末!$A$2:$E$284,2,FALSE),"不在") -> 【流山】石田拓海 | D27: 1010 | E27: =IFERROR(VLOOKUP(D27,電話端末!$A$2:$E$284,2,FALSE),"不在") -> 【流山】浅沼潤也 | F27: 1010 | G27: =IFERROR(VLOOKUP(F27,電話端末!$A$2:$D$284,2,FALSE),"不在") -> 【流山】浅沼潤也 | H27: 44 | I27: 36 | K27: 2.5101001e+19
A28: 45940.73 | B28: 3751 | C28: =IFERROR(VLOOKUP(B28,電話端末!$A$2:$E$284,2,FALSE),"不在") -> 【流山】鴻池千紗都 | D28: 5001 | E28: =IFERROR(VLOOKUP(D28,電話端末!$A$2:$E$284,2,FALSE),"不在") -> 【東京】着信グループ | F28: 3003 | G28: =IFERROR(VLOOKUP(F28,電話端末!$A$2:$D$284,2,FALSE),"不在") -> 【東京】林まど佳 | H28: 85 | I28: 83 | K28: 2.5101001e+19
A29: 45940.73 | B29: 3352 | C29: =IFERROR(VLOOKUP(B29,電話端末!$A$2:$E$284,2,FALSE),"不在") -> 【名古屋】大渕温子 | D29: 5004 | E29: =IFERROR(VLOOKUP(D29,電話端末!$A$2:$E$284,2,FALSE),"不在") -> 【埼玉】着信グループ | F29: 3156 | G29: =IFERROR(VLOOKUP(F29,電話端末!$A$2:$D$284,2,FALSE),"不在") -> 【埼玉】金子友希 | H29: 54 | I29: 50 | K29: 2.5101001e+19
A30: 45940.73 | B30: 3059 | C30: =IFERROR(VLOOKUP(B30,電話端末!$A$2:$E$284,2,FALSE),"不在") -> 【本社在庫物流課】黒田靖広 | D30: 1010 | E30: =IFERROR(VLOOKUP(D30,電話端末!$A$2:$E$284,2,FALSE),"不在") -> 【流山】浅沼潤也 | G30: =IFERROR(VLOOKUP(F30,電話端末!$A$2:$D$284,2,FALSE),"不在") -> 不在 | H30: 15 | I30: 0 | K30: 2.5101001e+19
A31: 45940.725 | B31: 3151 | C31: =IFERROR(VLOOKUP(B31,電話端末!$A$2:$E$284,2,FALSE),"不在") -> 【埼玉】池田千恵子 | D31: 2102 | E31: =IFERROR(VLOOKUP(D31,電話端末!$A$2:$E$284,2,FALSE),"不在") -> 【MF東京】櫻井美菜 | F31: 2105 | G31: =IFERROR(VLOOKUP(F31,電話端末!$A$2:$D$284,2,FALSE),"不在") -> 【MF東京】伊達幸子 | H31: 58 | I31: 52 | K31: 2.5101001e+19
A32: 45940.722 | B32: 3902 | C32: =IFERROR(VLOOKUP(B32,電話端末!$A$2:$E$284,2,FALSE),"不在") -> 【多摩】高久啓汰 | D32: 3107 | E32: =IFERROR(VLOOKUP(D32,電話端末!$A$2:$E$284,2,FALSE),"不在") -> 【横浜】中山満里奈 | F32: 3107 | G32: =IFERROR(VLOOKUP(F32,電話端末!$A$2:$D$284,2,FALSE),"不在") -> 【横浜】中山満里奈 | H32: 26 | I32: 23 | K32: 2.5101001e+19
A33: 45940.72 | B33: 3054 | C33: =IFERROR(VLOOKUP(B33,電話端末!$A$2:$E$284,2,FALSE),"不在") -> 【本社総務】吉田亜依 | D33: 2025 | E33: =IFERROR(VLOOKUP(D33,電話端末!$A$2:$E$284,2,FALSE),"不在") -> 【MF大阪】後垣幸恵 | F33: 2019 | G33: =IFERROR(VLOOKUP(F33,電話端末!$A$2:$D$284,2,FALSE),"不在") -> 【MF大阪】木下春河 | H33: 28 | I33: 21 | K33: 2.5101001e+19
A34: 45940.72 | B34: 2102 | C34: =IFERROR(VLOOKUP(B34,電話端末!$A$2:$E$284,2,FALSE),"不在") -> 【MF東京】櫻井美菜 | D34: 5004 | E34: =IFERROR(VLOOKUP(D34,電話端末!$A$2:$E$284,2,FALSE),"不在") -> 【埼玉】着信グループ | F34: 3154 | G34: =IFERROR(VLOOKUP(F34,電話端末!$A$2:$D$284,2,FALSE),"不在") -> 【埼玉】竹内梓 | H34: 103 | I34: 97 | K34: 2.5101001e+19
A35: 45940.714 | B35: 3055 | C35: =IFERROR(VLOOKUP(B35,電話端末!$A$2:$E$284,2,FALSE),"不在") -> 【本社総務】赤羽恵理 | D35: 2023 | E35: =IFERROR(VLOOKUP(D35,電話端末!$A$2:$E$284,2,FALSE),"不在") -> 【MF大阪】内田優美 | F35: 2011 | G35: =IFERROR(VLOOKUP(F35,電話端末!$A$2:$D$284,2,FALSE),"不在") -> 【MF大阪】上甲なつみ | H35: 46 | I35: 36 | K35: 2.5101001e+19
A36: 45940.714 | B36: 1504 | C36: =IFERROR(VLOOKUP(B36,電話端末!$A$2:$E$284,2,FALSE),"不在") -> 【岡山】岩佐寛子 | D36: 5190 | E36: =IFERROR(VLOOKUP(D36,電話端末!$A$2:$E$284,2,FALSE),"不在") -> 【福岡】着信グループ | F36: 3604 | G36: =IFERROR(VLOOKUP(F36,電話端末!$A$2:$D$284,2,FALSE),"不在") -> 【福岡】奥薗美和 | H36: 65 | I36: 60 | K36: 2.5101001e+19
A37: 45940.714 | B37: 1010 | C37: =IFERROR(VLOOKUP(B37,電話端末!$A$2:$E$284,2,FALSE),"不在") -> 【流山】浅沼潤也 | D37: 3751 | E37: =IFERROR(VLOOKUP(D37,電話端末!$A$2:$E$284,2,FALSE),"不在") -> 【流山】鴻池千紗都 | F37: 3751 | G37: =IFERROR(VLOOKUP(F37,電話端末!$A$2:$D$284,2,FALSE),"不在") -> 【流山】鴻池千紗都 | H37: 81 | I37: 79 | K37: 2.5101001e+19
A38: 45940.713 | B38: 1139 | C38: =IFERROR(VLOOKUP(B38,電話端末!$A$2:$E$284,2,FALSE),"不在") -> 【本社輸入】五戸勇気 | D38: 3103 | E38: =IFERROR(VLOOKUP(D38,電話端末!$A$2:$E$284,2,FALSE),"不在") -> 【横浜】舞智江 | F38: 3103 | G38: =IFERROR(VLOOKUP(F38,電話端末!$A$2:$D$284,2,FALSE),"不在") -> 【横浜】舞智江 | H38: 66 | I38: 64 | K38: 2.5101001e+19
A39: 45940.712 | B39: 3103 | C39: =IFERROR(VLOOKUP(B39,電話端末!$A$2:$E$284,2,FALSE),"不在") -> 【横浜】舞智江 | D39: 5551 | E39: =IFERROR(VLOOKUP(D39,電話端末!$A$2:$E$284,2,FALSE),"不在") -> 【本社】商品本部 | F39: 3059 | G39: =IFERROR(VLOOKUP(F39,電話端末!$A$2:$D$284,2,FALSE),"不在") -> 【本社在庫物流課】黒田靖広 | H39: 33 | I39: 26 | K39: 2.5101001e+19
A40: 45940.712 | B40: 3751 | C40: =IFERROR(VLOOKUP(B40,電話端末!$A$2:$E$284,2,FALSE),"不在") -> 【流山】鴻池千紗都 | D40: 3156 | E40: =IFERROR(VLOOKUP(D40,電話端末!$A$2:$E$284,2,FALSE),"不在") -> 【埼玉】金子友希 | F40: 3156 | G40: =IFERROR(VLOOKUP(F40,電話端末!$A$2:$D$284,2,FALSE),"不在") -> 【埼玉】金子友希 | H40: 124 | I40: 121 | K40: 2.5101001e+19
...

Sheet 外線発信
A1: 時刻 | B1: 発信番号 | C1: 発信者 | D1: 着信番号 | E1: 最終着信番号 | F1: 通話時間（応答までの時間を含む） | G1: 通話時間 | H1: メモ | I1: リクエストID
A2: 45941.484 | B2: 3008 | C2: =IFERROR(VLOOKUP(B2,電話端末!$A$2:$E$284,2,FALSE),"不在") -> 【東京】片桐芳夫 | D2: 0355347705 | E2: 0355347705 | F2: 35 | G2: 33 | I2: 2.51011e+19
A3: 45941.358 | B3: 1132 | C3: =IFERROR(VLOOKUP(B3,電話端末!$A$2:$E$284,2,FALSE),"不在") -> 【本社EC】鈴木浩允 | D3: 0474781253 | E3: 0474781253 | F3: 82 | G3: 73 | I3: 2.51011e+19
A4: 45940.789 | B4: 3601 | C4: =IFERROR(VLOOKUP(B4,電話端末!$A$2:$E$284,2,FALSE),"不在") -> 【福岡】松添愛 | D4: 08059443504 | E4: 08059443504 | F4: 43 | G4: 22 | I4: 2.5101001e+19
A5: 45940.782 | B5: 3601 | C5: =IFERROR(VLOOKUP(B5,電話端末!$A$2:$E$284,2,FALSE),"不在") -> 【福岡】松添愛 | D5: 08043858622 | E5: 08043858622 | F5: 46 | G5: 33 | I5: 2.5101001e+19
A6: 45940.781 | B6: 3601 | C6: =IFERROR(VLOOKUP(B6,電話端末!$A$2:$E$284,2,FALSE),"不在") -> 【福岡】松添愛 | D6: 09018418505 | E6: 09018418505 | F6: 51 | G6: 37 | I6: 2.5101001e+19
A7: 45940.773 | B7: 3603 | C7: =IFERROR(VLOOKUP(B7,電話端末!$A$2:$E$284,2,FALSE),"不在") -> 【福岡】重松宝成 | D7: 0828318380 | E7: 0828318380 | F7: 12 | G7: 7 | I7: 2.5101001e+19
A8: 45940.767 | B8: 3600 | C8: =IFERROR(VLOOKUP(B8,電話端末!$A$2:$E$284,2,FALSE),"不在") -> 【福岡】松尾明日香 | D8: 08065938785 | E8: 08065938785 | F8: 119 | G8: 107 | I8: 2.5101001e+19
A9: 45940.763 | B9: 3600 | C9: =IFERROR(VLOOKUP(B9,電話端末!$A$2:$E$284,2,FALSE),"不在") -> 【福岡】松尾明日香 | D9: 08034217212 | E9: 08034217212 | F9: 226 | G9: 209 | I9: 2.5101001e+19
A10: 45940.761 | B10: 3604 | C10: =IFERROR(VLOOKUP(B10,電話端末!$A$2:$E$284,2,FALSE),"不在") -> 【福岡】奥薗美和 | D10: 08066164282 | E10: 08066164282 | F10: 110 | G10: 99 | I10: 2.5101001e+19
A11: 45940.761 | B11: 3059 | C11: =IFERROR(VLOOKUP(B11,電話端末!$A$2:$E$284,2,FALSE),"不在") -> 【本社在庫物流課】黒田靖広 | D11: 0661507701 | E11: 0661507701 | F11: 91 | G11: 87 | I11: 2.5101001e+19
A12: 45940.759 | B12: 3751 | C12: =IFERROR(VLOOKUP(B12,電話端末!$A$2:$E$284,2,FALSE),"不在") -> 【流山】鴻池千紗都 | D12: 0358577595 | E12: 0358577595 | F12: 125 | G12: 113 | I12: 2.5101001e+19
A13: 45940.758 | B13: 3500 | C13: =IFERROR(VLOOKUP(B13,電話端末!$A$2:$E$284,2,FALSE),"不在") -> 【岡山】矢野夏絵 | D13: 08059443503 | E13: 08059443503 | F13: 30 | G13: 22 | I13: 2.5101001e+19
... A15: 45940.757 | B15: 1504 | C15: =IFERROR(VLOOKUP(B15,電話端末!$A$2:$E$284,2,FALSE),"不在") -> 【岡山】岩佐寛子 | D15: 09093562144 | E15: 09093562144 | F15: 86 | G15: 76 | I15: 2.5101001e+19
A16: 45940.756 | B16: 3508 | C16: =IFERROR(VLOOKUP(B16,電話端末!$A$2:$E$284,2,FALSE),"不在") -> 【岡山】岸本麻衣子 | D16: 09035284665 | F16: 3 | G16: 0 | I16: 2.5101001e+19
A17: 45940.754 | B17: 1010 | C17: =IFERROR(VLOOKUP(B17,電話端末!$A$2:$E$284,2,FALSE),"不在") -> 【流山】浅沼潤也 | D17: 08051749007 | E17: 08051749007 | F17: 103 | G17: 95 | I17: 2.5101001e+19
A18: 45940.754 | B18: 3151 | C18: =IFERROR(VLOOKUP(B18,電話端末!$A$2:$E$284,2,FALSE),"不在") -> 【埼玉】池田千恵子 | D18: 08059443511 | F18: 22 | G18: 0 | I18: 2.5101001e+19
A19: 45940.752 | B19: 3250 | C19: =IFERROR(VLOOKUP(B19,電話端末!$A$2:$E$284,2,FALSE),"不在") -> 【仙台】仁藤佳美 | D19: 08056505277 | E19: 08056505277 | F19: 144 | G19: 138 | I19: 2.5101001e+19
A20: 45940.752 | B20: 3752 | C20: =IFERROR(VLOOKUP(B20,電話端末!$A$2:$E$284,2,FALSE),"不在") -> 【流山】石田拓海 | D20: 08059536550 | E20: 08059536550 | F20: 161 | G20: 146 | I20: 2.5101001e+19
A21: 45940.747 | B21: 3502 | C21: =IFERROR(VLOOKUP(B21,電話端末!$A$2:$E$284,2,FALSE),"不在") -> 【岡山】伊藤優 | D21: 08059443501 | E21: 08059443501 | F21: 135 | G21: 128 | I21: 2.5101001e+19
A22: 45940.747 | B22: 3500 | C22: =IFERROR(VLOOKUP(B22,電話端末!$A$2:$E$284,2,FALSE),"不在") -> 【岡山】矢野夏絵 | D22: 09035284665 | F22: 4 | G22: 0 | I22: 2.5101001e+19
A23: 45940.747 | B23: 3161 | C23: =IFERROR(VLOOKUP(B23,電話端末!$A$2:$E$284,2,FALSE),"不在") -> 【埼玉】久保貴志 | D23: 0484723829 | E23: 0484723829 | F23: 47 | G23: 36 | I23: 2.5101001e+19
A24: 45940.746 | B24: 3500 | C24: =IFERROR(VLOOKUP(B24,電話端末!$A$2:$E$284,2,FALSE),"不在") -> 【岡山】矢野夏絵 | D24: 09035284844 | E24: 09035284844 | F24: 16 | G24: 4 | I24: 2.5101001e+19
A25: 45940.746 | B25: 3158 | C25: =IFERROR(VLOOKUP(B25,電話端末!$A$2:$E$284,2,FALSE),"不在") -> 【埼玉】関野和彦 | D25: 0339344670 | E25: 0339344670 | F25: 49 | G25: 44 | I25: 2.5101001e+19
A26: 45940.745 | B26: 3156 | C26: =IFERROR(VLOOKUP(B26,電話端末!$A$2:$E$284,2,FALSE),"不在") -> 【埼玉】金子友希 | D26: 08052373246 | E26: 08052373246 | F26: 4 | G26: 0 | I26: 2.5101001e+19
A27: 45940.744 | B27: 2016 | C27: =IFERROR(VLOOKUP(B27,電話端末!$A$2:$E$284,2,FALSE),"不在") -> 【MF大阪】濱尾香 | D27: 0248923890 | E27: 0248923890 | F27: 41 | G27: 37 | I27: 2.5101001e+19
A28: 45940.744 | B28: 1504 | C28: =IFERROR(VLOOKUP(B28,電話端末!$A$2:$E$284,2,FALSE),"不在") -> 【岡山】岩佐寛子 | D28: 08059443501 | E28: 08059443501 | F28: 71 | G28: 56 | I28: 2.5101001e+19
A29: 45940.743 | B29: 3250 | C29: =IFERROR(VLOOKUP(B29,電話端末!$A$2:$E$284,2,FALSE),"不在") -> 【仙台】仁藤佳美 | D29: 0661507701 | E29: 0661507701 | F29: 97 | G29: 93 | I29: 2.5101001e+19
A30: 45940.742 | B30: 3152 | C30: =IFERROR(VLOOKUP(B30,電話端末!$A$2:$E$284,2,FALSE),"不在") -> 【埼玉】細田昌子 | D30: 0492221238 | E30: 0492221238 | F30: 47 | G30: 35 | I30: 2.5101001e+19
A31: 45940.742 | B31: 1504 | C31: =IFERROR(VLOOKUP(B31,電話端末!$A$2:$E$284,2,FALSE),"不在") -> 【岡山】岩佐寛子 | D31: 0676362343 | E31: 0676362343 | F31: 4 | G31: 3 | I31: 2.5101001e+19
A32: 45940.742 | B32: 3155 | C32: =IFERROR(VLOOKUP(B32,電話端末!$A$2:$E$284,2,FALSE),"不在") -> 【埼玉】吉田夏子 | D32: 0487523160 | E32: 0487523160 | F32: 92 | G32: 87 | I32: 2.5101001e+19
A33: 45940.74 | B33: 3203 | C33: =IFERROR(VLOOKUP(B33,電話端末!$A$2:$E$284,2,FALSE),"不在") -> 【札幌】山田明貴人 | D33: 0133762921 | E33: 0133762921 | F33: 130 | G33: 127 | I33: 2.5101001e+19
A34: 45940.739 | B34: 3156 | C34: =IFERROR(VLOOKUP(B34,電話端末!$A$2:$E$284,2,FALSE),"不在") -> 【埼玉】金子友希 | D34: 0356080101 | E34: 0356080101 | F34: 64 | G34: 60 | I34: 2.5101001e+19
... A41: 45940.736 | B41: 3203 | C41: =IFERROR(VLOOKUP(B41,電話端末!$A$2:$E$284,2,FALSE),"不在") -> 【札幌】山田明貴人 | D41: 0133762921 | E41: 0133762921 | F41: 112 | G41: 107 | I41: 2.5101001e+19
A42: 45940.736 | B42: 3203 | C42: =IFERROR(VLOOKUP(B42,電話端末!$A$2:$E$284,2,FALSE),"不在") -> 【札幌】山田明貴人 | D42: 013376296 | F42: 0 | G42: 0 | I42: 2.5101001e+19
A43: 45940.735 | B43: 3152 | C43: =IFERROR(VLOOKUP(B43,電話端末!$A$2:$E$284,2,FALSE),"不在") -> 【埼玉】細田昌子 | D43: 08083225092 | E43: 08083225092 | F43: 157 | G43: 149 | I43: 2.5101001e+19
A44: 45940.734 | B44: 3751 | C44: =IFERROR(VLOOKUP(B44,電話端末!$A$2:$E$284,2,FALSE),"不在") -> 【流山】鴻池千紗都 | D44: 08026566000 | F44: 22 | G44: 0 | I44: 2.5101001e+19
A45: 45940.734 | B45: 3500 | C45: =IFERROR(VLOOKUP(B45,電話端末!$A$2:$E$284,2,FALSE),"不在") -> 【岡山】矢野夏絵 | D45: 0667817004 | E45: 0667817004 | F45: 13 | G45: 9 | I45: 2.5101001e+19
A46: 45940.734 | B46: 3257 | C46: =IFERROR(VLOOKUP(B46,電話端末!$A$2:$E$284,2,FALSE),"不在") -> 【仙台】齋藤詩織 | D46: 0225233701 | E46: 0225233701 | F46: 50 | G46: 40 | I46: 2.5101001e+19
A47: 45940.733 | B47: 3251 | C47: =IFERROR(VLOOKUP(B47,電話端末!$A$2:$E$284,2,FALSE),"不在") -> 【仙台】阿部かおり | D47: 0223887741 | E47: 0223887741 | F47: 53 | G47: 47 | I47: 2.5101001e+19
...

Sheet 外線着信
A1: 時刻 | B1: 発信番号 | C1: 着信番号 | D1: 着信者 | E1: 最終着信番号 | F1: 最終着信者 | G1: 通話時間（応答までの時間を含む） | H1: 通話時間 | I1: メモ | J1: リクエストID
A2: 45942.837 | B2: 09088940099 | C2: 5550 | D2: =IFERROR(VLOOKUP(C2,電話端末!$A$2:$E$284,2,FALSE),"不在") -> 【本社】代表 | F2: =IFERROR(VLOOKUP(E2,電話端末!$A$2:$E$284,2,FALSE),"不在") -> 不在 | G2: 0 | H2: 0 | J2: 2.51012e+19
A3: 45942.35 | B3: 08055445094 | C3: 5280 | D3: =IFERROR(VLOOKUP(C3,電話端末!$A$2:$E$284,2,FALSE),"不在") -> 【横浜】着信グループ | F3: =IFERROR(VLOOKUP(E3,電話端末!$A$2:$E$284,2,FALSE),"不在") -> 不在 | G3: 1 | H3: 0 | J3: 2.51012e+19
A4: 45941.628 | B4: 0562467225 | C4: 5390 | D4: =IFERROR(VLOOKUP(C4,電話端末!$A$2:$E$284,2,FALSE),"不在") -> 【名古屋】着信グループ | F4: =IFERROR(VLOOKUP(E4,電話端末!$A$2:$E$284,2,FALSE),"不在") -> 不在 | G4: 11 | H4: 0 | J4: 2.51011e+19
A5: 45941.622 | B5: 18772382178 | C5: 5690 | D5: =IFERROR(VLOOKUP(C5,電話端末!$A$2:$E$284,2,FALSE),"不在") -> 【広島】着信グループ | F5: =IFERROR(VLOOKUP(E5,電話端末!$A$2:$E$284,2,FALSE),"不在") -> 不在 | G5: 18 | H5: 0 | J5: 2.51011e+19
A6: 45941.622 | B6: 09039625899 | C6: 5190 | D6: =IFERROR(VLOOKUP(C6,電話端末!$A$2:$E$284,2,FALSE),"不在") -> 【福岡】着信グループ | F6: =IFERROR(VLOOKUP(E6,電話端末!$A$2:$E$284,2,FALSE),"不在") -> 不在 | G6: 10 | H6: 0 | J6: 2.51011e+19
A7: 45941.598 | B7: 08035104192 | C7: 5880 | D7: =IFERROR(VLOOKUP(C7,電話端末!$A$2:$E$284,2,FALSE),"不在") -> 【札幌】着信グループ | F7: =IFERROR(VLOOKUP(E7,電話端末!$A$2:$E$284,2,FALSE),"不在") -> 不在 | G7: 0 | H7: 0 | J7: 2.51011e+19
A8: 45941.568 | B8: 0355347705 | C8: 5001 | D8: =IFERROR(VLOOKUP(C8,電話端末!$A$2:$E$284,2,FALSE),"不在") -> 【東京】着信グループ | F8: =IFERROR(VLOOKUP(E8,電話端末!$A$2:$E$284,2,FALSE),"不在") -> 不在 | G8: 30 | H8: 0 | J8: 2.51011e+19
A9: 45941.521 | B9: 07084890762 | C9: 5390 | D9: =IFERROR(VLOOKUP(C9,電話端末!$A$2:$E$284,2,FALSE),"不在") -> 【名古屋】着信グループ | F9: =IFERROR(VLOOKUP(E9,電話端末!$A$2:$E$284,2,FALSE),"不在") -> 不在 | G9: 17 | H9: 0 | J9: 2.51011e+19
A10: 45941.52 | B10: 0859333871 | C10: 5580 | D10: =IFERROR(VLOOKUP(C10,電話端末!$A$2:$E$284,2,FALSE),"不在") -> 【岡山】着信グループ | F10: =IFERROR(VLOOKUP(E10,電話端末!$A$2:$E$284,2,FALSE),"不在") -> 不在 | G10: 2 | H10: 0 | J10: 2.51011e+19
A11: 45941.48 | B11: 0775772320 | C11: 5490 | D11: =IFERROR(VLOOKUP(C11,電話端末!$A$2:$E$284,2,FALSE),"不在") -> 【滋賀】着信グループ | F11: =IFERROR(VLOOKUP(E11,電話端末!$A$2:$E$284,2,FALSE),"不在") -> 不在 | G11: 17 | H11: 0 | J11: 2.51011e+19
A12: 45941.478 | B12: 0355347705 | C12: 5001 | D12: =IFERROR(VLOOKUP(C12,電話端末!$A$2:$E$284,2,FALSE),"不在") -> 【東京】着信グループ | F12: =IFERROR(VLOOKUP(E12,電話端末!$A$2:$E$284,2,FALSE),"不在") -> 不在 | G12: 21 | H12: 0 | J12: 2.51011e+19
A13: 45941.472 | B13: 0355347705 | C13: 5001 | D13: =IFERROR(VLOOKUP(C13,電話端末!$A$2:$E$284,2,FALSE),"不在") -> 【東京】着信グループ | E13: 3008 | F13: =IFERROR(VLOOKUP(E13,電話端末!$A$2:$E$284,2,FALSE),"不在") -> 【東京】片桐芳夫 | G13: 37 | H13: 33 | J13: 2.51011e+19
A14: 45941.46 | B14: 0355347705 | C14: 5001 | D14: =IFERROR(VLOOKUP(C14,電話端末!$A$2:$E$284,2,FALSE),"不在") -> 【東京】着信グループ | E14: 3008 | F14: =IFERROR(VLOOKUP(E14,電話端末!$A$2:$E$284,2,FALSE),"不在") -> 【東京】片桐芳夫 | G14: 50 | H14: 44 | J14: 2.51011e+19
A15: 45941.438 | B15: 0243234879 | C15: 5790 | D15: =IFERROR(VLOOKUP(C15,電話端末!$A$2:$E$284,2,FALSE),"不在") -> 【仙台】着信グループ | F15: =IFERROR(VLOOKUP(E15,電話端末!$A$2:$E$284,2,FALSE),"不在") -> 不在 | G15: 5 | H15: 0 | J15: 2.51011e+19
A16: 45941.422 | B16: 08068435891 | C16: 5190 | D16: =IFERROR(VLOOKUP(C16,電話端末!$A$2:$E$284,2,FALSE),"不在") -> 【福岡】着信グループ | F16: =IFERROR(VLOOKUP(E16,電話端末!$A$2:$E$284,2,FALSE),"不在") -> 不在 | G16: 3 | H16: 0 | J16: 2.51011e+19
A17: 45941.352 | B17: 0355347705 | C17: 5001 | D17: =IFERROR(VLOOKUP(C17,電話端末!$A$2:$E$284,2,FALSE),"不在") -> 【東京】着信グループ | E17: 3010 | F17: =IFERROR(VLOOKUP(E17,電話端末!$A$2:$E$284,2,FALSE),"不在") -> 【東京】豊島亮 | G17: 38 | H17: 32 | J17: 2.51011e+19
A18: 45941.312 | B18: 08067416399 | C18: 5580 | D18: =IFERROR(VLOOKUP(C18,電話端末!$A$2:$E$284,2,FALSE),"不在") -> 【岡山】着信グループ | F18: =IFERROR(VLOOKUP(E18,電話端末!$A$2:$E$284,2,FALSE),"不在") -> 不在 | G18: 6 | H18: 0 | J18: 2.51011e+19
A19: 45940.838 | B19: 08059443501 | C19: 5580 | D19: =IFERROR(VLOOKUP(C19,電話端末!$A$2:$E$284,2,FALSE),"不在") -> 【岡山】着信グループ | F19: =IFERROR(VLOOKUP(E19,電話端末!$A$2:$E$284,2,FALSE),"不在") -> 不在 | G19: 19 | H19: 0 | J19: 2.5101001e+19
A20: 45940.788 | B20: 08060387508 | C20: 5880 | D20: =IFERROR(VLOOKUP(C20,電話端末!$A$2:$E$284,2,FALSE),"不在") -> 【札幌】着信グループ | F20: =IFERROR(VLOOKUP(E20,電話端末!$A$2:$E$284,2,FALSE),"不在") -> 不在 | G20: 1 | H20: 0 | J20: 2.5101001e+19
A21: 45940.775 | B21: 09044503232 | C21: 5004 | D21: =IFERROR(VLOOKUP(C21,電話端末!$A$2:$E$284,2,FALSE),"不在") -> 【埼玉】着信グループ | F21: =IFERROR(VLOOKUP(E21,電話端末!$A$2:$E$284,2,FALSE),"不在") -> 不在 | G21: 14 | H21: 0 | J21: 2.5101001e+19
A22: 45940.775 | B22: 09044503232 | C22: 5004 | D22: =IFERROR(VLOOKUP(C22,電話端末!$A$2:$E$284,2,FALSE),"不在") -> 【埼玉】着信グループ | F22: =IFERROR(VLOOKUP(E22,電話端末!$A$2:$E$284,2,FALSE),"不在") -> 不在 | G22: 15 | H22: 0 | J22: 2.5101001e+19
A23: 45940.774 | B23: 08068601880 | C23: 5880 | D23: =IFERROR(VLOOKUP(C23,電話端末!$A$2:$E$284,2,FALSE),"不在") -> 【札幌】着信グループ | F23: =IFERROR(VLOOKUP(E23,電話端末!$A$2:$E$284,2,FALSE),"不在") -> 不在 | G23: 16 | H23: 0 | J23: 2.5101001e+19
A24: 45940.773 | B24: 08059536550 | C24: 5003 | D24: =IFERROR(VLOOKUP(C24,電話端末!$A$2:$E$284,2,FALSE),"不在") -> 【流山】着信グループ | E24: 3752 | F24: =IFERROR(VLOOKUP(E24,電話端末!$A$2:$E$284,2,FALSE),"不在") -> 【流山】石田拓海 | G24: 192 | H24: 187 | J24: 2.5101001e+19
A25: 45940.768 | B25: 09061533655 | C25: 5790 | D25: =IFERROR(VLOOKUP(C25,電話端末!$A$2:$E$284,2,FALSE),"不在") -> 【仙台】着信グループ | F25: =IFERROR(VLOOKUP(E25,電話端末!$A$2:$E$284,2,FALSE),"不在") -> 不在 | G25: 8 | H25: 0 | J25: 2.5101001e+19
A26: 45940.768 | B26: 09026880278 | C26: 5001 | D26: =IFERROR(VLOOKUP(C26,電話端末!$A$2:$E$284,2,FALSE),"不在") -> 【東京】着信グループ | F26: =IFERROR(VLOOKUP(E26,電話端末!$A$2:$E$284,2,FALSE),"不在") -> 不在 | G26: 23 | H26: 0 | J26: 2.5101001e+19
A27: 45940.768 | B27: 08067416399 | C27: 5580 | D27: =IFERROR(VLOOKUP(C27,電話端末!$A$2:$E$284,2,FALSE),"不在") -> 【岡山】着信グループ | F27: =IFERROR(VLOOKUP(E27,電話端末!$A$2:$E$284,2,FALSE),"不在") -> 不在 | G27: 20 | H27: 0 | J27: 2.5101001e+19
A28: 45940.768 | B28: 09044503232 | C28: 5280 | D28: =IFERROR(VLOOKUP(C28,電話端末!$A$2:$E$284,2,FALSE),"不在") -> 【横浜】着信グループ | E28: 3110 | F28: =IFERROR(VLOOKUP(E28,電話端末!$A$2:$E$284,2,FALSE),"不在") -> 【横浜】田鹿僚志 | G28: 117 | H28: 110 | J28: 2.5101001e+19
A29: 45940.766 | B29: 08059443511 | C29: 5004 | D29: =IFERROR(VLOOKUP(C29,電話端末!$A$2:$E$284,2,FALSE),"不在") -> 【埼玉】着信グループ | E29: 3151 | F29: =IFERROR(VLOOKUP(E29,電話端末!$A$2:$E$284,2,FALSE),"不在") -> 【埼玉】池田千恵子 | G29: 368 | H29: 364 | J29: 2.5101001e+19
A30: 45940.76 | B30: 09035393319 | C30: 5004 | D30: =IFERROR(VLOOKUP(C30,電話端末!$A$2:$E$284,2,FALSE),"不在") -> 【埼玉】着信グループ | F30: =IFERROR(VLOOKUP(E30,電話端末!$A$2:$E$284,2,FALSE),"不在") -> 不在 | G30: 27 | H30: 0 | J30: 2.5101001e+19
A31: 45940.759 | B31: 0726696541 | C31: 5295 | D31: =IFERROR(VLOOKUP(C31,電話端末!$A$2:$E$284,2,FALSE),"不在") -> 【大阪】着信グループ(外線) | F31: =IFERROR(VLOOKUP(E31,電話端末!$A$2:$E$284,2,FALSE),"不在") -> 不在 | G31: 14 | H31: 0 | J31: 2.5101001e+19
A32: 45940.758 | B32: 07065211699 | C32: 5500 | D32: =IFERROR(VLOOKUP(C32,電話端末!$A$2:$E$284,2,FALSE),"不在") -> 【MF大阪】着信グループ | F32: =IFERROR(VLOOKUP(E32,電話端末!$A$2:$E$284,2,FALSE),"不在") -> 不在 | G32: 21 | H32: 0 | J32: 2.5101001e+19
A33: 45940.758 | B33: 08055387378 | C33: 5490 | D33: =IFERROR(VLOOKUP(C33,電話端末!$A$2:$E$284,2,FALSE),"不在") -> 【滋賀】着信グループ | F33: =IFERROR(VLOOKUP(E33,電話端末!$A$2:$E$284,2,FALSE),"不在") -> 不在 | G33: 15 | H33: 0 | J33: 2.5101001e+19
A34: 45940.756 | B34: 0535420112 | C34: 5580 | D34: =IFERROR(VLOOKUP(C34,電話端末!$A$2:$E$284,2,FALSE),"不在") -> 【岡山】着信グループ | F34: =IFERROR(VLOOKUP(E34,電話端末!$A$2:$E$284,2,FALSE),"不在") -> 不在 | G34: 20 | H34: 0 | J34: 2.5101001e+19
A35: 45940.756 | B35: 08059536550 | C35: 5003 | D35: =IFERROR(VLOOKUP(C35,電話端末!$A$2:$E$284,2,FALSE),"不在") -> 【流山】着信グループ | E35: 3752 | F35: =IFERROR(VLOOKUP(E35,電話端末!$A$2:$E$284,2,FALSE),"不在") -> 【流山】石田拓海 | G35: 316 | H35: 314 | J35: 2.5101001e+19
A36: 45940.756 | B36: 05020180622 | C36: 5580 | D36: =IFERROR(VLOOKUP(C36,電話端末!$A$2:$E$284,2,FALSE),"不在") -> 【岡山】着信グループ | F36: =IFERROR(VLOOKUP(E36,電話端末!$A$2:$E$284,2,FALSE),"不在") -> 不在 | G36: 2 | H36: 0 | J36: 2.5101001e+19
A37: 45940.756 | B37: 08059443511 | C37: 5004 | D37: =IFERROR(VLOOKUP(C37,電話端末!$A$2:$E$284,2,FALSE),"不在") -> 【埼玉】着信グループ | E37: 3151 | F37: =IFERROR(VLOOKUP(E37,電話端末!$A$2:$E$284,2,FALSE),"不在") -> 【埼玉】池田千恵子 | G37: 54 | H37: 50 | J37: 2.5101001e+19
A38: 45940.751 | B38: 09093801802 | C38: 5001 | D38: =IFERROR(VLOOKUP(C38,電話端末!$A$2:$E$284,2,FALSE),"不在") -> 【東京】着信グループ | F38: =IFERROR(VLOOKUP(E38,電話端末!$A$2:$E$284,2,FALSE),"不在") -> 不在 | G38: 14 | H38: 0 | J38: 2.5101001e+19
A39: 45940.749 | B39: 08026566000 | C39: 5003 | D39: =IFERROR(VLOOKUP(C39,電話端末!$A$2:$E$284,2,FALSE),"不在") -> 【流山】着信グループ | E39: 3752 | F39: =IFERROR(VLOOKUP(E39,電話端末!$A$2:$E$284,2,FALSE),"不在") -> 【流山】石田拓海 | G39: 71 | H39: 68 | J39: 2.5101001e+19
A40: 45940.748 | B40: 08062928589 | C40: 5790 | D40: =IFERROR(VLOOKUP(C40,電話端末!$A$2:$E$284,2,FALSE),"不在") -> 【仙台】着信グループ | E40: 3251 | F40: =IFERROR(VLOOKUP(E40,電話端末!$A$2:$E$284,2,FALSE),"不在") -> 【仙台】阿部かおり | G40: 36 | H40: 33 | J40: 2.5101001e+19
...
