Workbook

Sheet Report_着信
A1: 1. 拠点別 着信件数
A3: 拠点 | B3: 内線_入電 | C3: 内線_着電 | D3: 外線_入電 | E3: 外線_着電 | F3: 他拠点へ転送 | G3: 他拠点から転送
A4: =IF(RawData_着信!A2="","", RawData_着信!A2) -> 東京 | B4: =IF(RawData_着信!B2="","", RawData_着信!B2) -> 447 | C4: =IF(RawData_着信!C2="","", RawData_着信!C2) -> 366 | D4: =IF(RawData_着信!D2="","", RawData_着信!D2) -> 5866 | E4: =IF(RawData_着信!E2="","", RawData_着信!E2) -> 5751 | F4: =IF(RawData_着信!F2="","", RawData_着信!F2) | G4: =IF(RawData_着信!G2="","", RawData_着信!G2) -> 流山
A5: =IF(RawData_着信!A3="","", RawData_着信!A3) -> 横浜 | B5: =IF(RawData_着信!B3="","", RawData_着信!B3) -> 532 | C5: =IF(RawData_着信!C3="","", RawData_着信!C3) -> 425 | D5: =IF(RawData_着信!D3="","", RawData_着信!D3) -> 6626 | E5: =IF(RawData_着信!E3="","", RawData_着信!E3) -> 6635 | F5: =IF(RawData_着信!F3="","", RawData_着信!F3) | G5: =IF(RawData_着信!G3="","", RawData_着信!G3) -> 多摩
A6: =IF(RawData_着信!A4="","", RawData_着信!A4) -> 埼玉 | B6: =IF(RawData_着信!B4="","", RawData_着信!B4) -> 427 | C6: =IF(RawData_着信!C4="","", RawData_着信!C4) -> 324 | D6: =IF(RawData_着信!D4="","", RawData_着信!D4) -> 5168 | E6: =IF(RawData_着信!E4="","", RawData_着信!E4) -> 5597 | F6: =IF(RawData_着信!F4="","", RawData_着信!F4) | G6: =IF(RawData_着信!G4="","", RawData_着信!G4) -> 千葉・北関東
A7: =IF(RawData_着信!A5="","", RawData_着信!A5) -> 滋賀 | B7: =IF(RawData_着信!B5="","", RawData_着信!B5) -> 120 | C7: =IF(RawData_着信!C5="","", RawData_着信!C5) -> 94 | D7: =IF(RawData_着信!D5="","", RawData_着信!D5) -> 1683 | E7: =IF(RawData_着信!E5="","", RawData_着信!E5) -> 1773 | F7: =IF(RawData_着信!F5="","", RawData_着信!F5) | G7: =IF(RawData_着信!G5="","", RawData_着信!G5) -> 金沢
A8: =IF(RawData_着信!A6="","", RawData_着信!A6) -> 大阪 | B8: =IF(RawData_着信!B6="","", RawData_着信!B6) -> 316 | C8: =IF(RawData_着信!C6="","", RawData_着信!C6) -> 255 | D8: =IF(RawData_着信!D6="","", RawData_着信!D6) -> 1292 | E8: =IF(RawData_着信!E6="","", RawData_着信!E6) -> 212 | F8: =IF(RawData_着信!F6="","", RawData_着信!F6) -> 岡山 | G8: =IF(RawData_着信!G6="","", RawData_着信!G6)
A9: =IF(RawData_着信!A7="","", RawData_着信!A7) -> 千葉 | B9: =IF(RawData_着信!B7="","", RawData_着信!B7) -> 387 | C9: =IF(RawData_着信!C7="","", RawData_着信!C7) -> 292 | D9: =IF(RawData_着信!D7="","", RawData_着信!D7) -> 2110 | E9: =IF(RawData_着信!E7="","", RawData_着信!E7) -> 1551 | F9: =IF(RawData_着信!F7="","", RawData_着信!F7) -> 埼玉 | G9: =IF(RawData_着信!G7="","", RawData_着信!G7)
A10: =IF(RawData_着信!A8="","", RawData_着信!A8) -> 福岡 | B10: =IF(RawData_着信!B8="","", RawData_着信!B8) -> 1356 | C10: =IF(RawData_着信!C8="","", RawData_着信!C8) -> 1214 | D10: =IF(RawData_着信!D8="","", RawData_着信!D8) -> 4135 | E10: =IF(RawData_着信!E8="","", RawData_着信!E8) -> 4006 | F10: =IF(RawData_着信!F8="","", RawData_着信!F8) | G10: =IF(RawData_着信!G8="","", RawData_着信!G8) -> 広島・熊本
A11: =IF(RawData_着信!A9="","", RawData_着信!A9) -> 岡山 | B11: =IF(RawData_着信!B9="","", RawData_着信!B9) -> 412 | C11: =IF(RawData_着信!C9="","", RawData_着信!C9) -> 283 | D11: =IF(RawData_着信!D9="","", RawData_着信!D9) -> 2898 | E11: =IF(RawData_着信!E9="","", RawData_着信!E9) -> 4460 | F11: =IF(RawData_着信!F9="","", RawData_着信!F9) | G11: =IF(RawData_着信!G9="","", RawData_着信!G9) -> 大阪・静岡
A12: =IF(RawData_着信!A10="","", RawData_着信!A10) -> 名古屋 | B12: =IF(RawData_着信!B10="","", RawData_着信!B10) -> 648 | C12: =IF(RawData_着信!C10="","", RawData_着信!C10) -> 605 | D12: =IF(RawData_着信!D10="","", RawData_着信!D10) -> 2028 | E12: =IF(RawData_着信!E10="","", RawData_着信!E10) -> 1940 | F12: =IF(RawData_着信!F10="","", RawData_着信!F10) | G12: =IF(RawData_着信!G10="","", RawData_着信!G10)
A13: =IF(RawData_着信!A11="","", RawData_着信!A11) -> 仙台 | B13: =IF(RawData_着信!B11="","", RawData_着信!B11) -> 400 | C13: =IF(RawData_着信!C11="","", RawData_着信!C11) -> 246 | D13: =IF(RawData_着信!D11="","", RawData_着信!D11) -> 4499 | E13: =IF(RawData_着信!E11="","", RawData_着信!E11) -> 4619 | F13: =IF(RawData_着信!F11="","", RawData_着信!F11) | G13: =IF(RawData_着信!G11="","", RawData_着信!G11) -> 札幌
A14: =IF(RawData_着信!A12="","", RawData_着信!A12) -> 流山 | B14: =IF(RawData_着信!B12="","", RawData_着信!B12) -> 504 | C14: =IF(RawData_着信!C12="","", RawData_着信!C12) -> 343 | D14: =IF(RawData_着信!D12="","", RawData_着信!D12) -> 780 | E14: =IF(RawData_着信!E12="","", RawData_着信!E12) -> 695 | F14: =IF(RawData_着信!F12="","", RawData_着信!F12) | G14: =IF(RawData_着信!G12="","", RawData_着信!G12)
A15: =IF(RawData_着信!A13="","", RawData_着信!A13) -> 本社 | B15: =IF(RawData_着信!B13="","", RawData_着信!B13) -> 230 | C15: =IF(RawData_着信!C13="","", RawData_着信!C13) -> 0 | D15: =IF(RawData_着信!D13="","", RawData_着信!D13) -> 1061 | E15: =IF(RawData_着信!E13="","", RawData_着信!E13) -> 0 | F15: =IF(RawData_着信!F13="","", RawData_着信!F13) | G15: =IF(RawData_着信!G13="","", RawData_着信!G13)
... A53: =IF(RawData_着信!A51="","", RawData_着信!A51) | B53: =IF(RawData_着信!B51="","", RawData_着信!B51) | C53: =IF(RawData_着信!C51="","", RawData_着信!C51) | D53: =IF(RawData_着信!D51="","", RawData_着信!D51) | E53: =IF(RawData_着信!E51="","", RawData_着信!E51) | F53: =IF(RawData_着信!F51="","", RawData_着信!F51) | G53: =IF(RawData_着信!G51="","", RawData_着信!G51)

Sheet RawData_着信
A1: 拠点 | B1: 内線_入電 | C1: 内線_着電 | D1: 外線_入電 | E1: 外線_着電 | F1: 他拠点へ転送 | G1: 他拠点から転送
A2: 東京 | B2: 447 | C2: 366 | D2: 5866 | E2: 5751 | G2: 流山
A3: 横浜 | B3: 532 | C3: 425 | D3: 6626 | E3: 6635 | G3: 多摩
A4: 埼玉 | B4: 427 | C4: 324 | D4: 5168 | E4: 5597 | G4: 千葉・北関東
A5: 滋賀 | B5: 120 | C5: 94 | D5: 1683 | E5: 1773 | G5: 金沢
A6: 大阪 | B6: 316 | C6: 255 | D6: 1292 | E6: 212 | F6: 岡山
A7: 千葉 | B7: 387 | C7: 292 | D7: 2110 | E7: 1551 | F7: 埼玉
A8: 福岡 | B8: 1356 | C8: 1214 | D8: 4135 | E8: 4006 | G8: 広島・熊本
A9: 岡山 | B9: 412 | C9: 283 | D9: 2898 | E9: 4460 | G9: 大阪・静岡
A10: 名古屋 | B10: 648 | C10: 605 | D10: 2028 | E10: 1940
A11: 仙台 | B11: 400 | C11: 246 | D11: 4499 | E11: 4619 | G11: 札幌
A12: 流山 | B12: 504 | C12: 343 | D12: 780 | E12: 695
A13: 本社 | B13: 230 | C13: 0 | D13: 1061 | E13: 0
A14: 札幌 | B14: 180 | C14: 89 | D14: 395 | E14: 28
A15: 本社IT | B15: 211 | C15: 159 | D15: 0 | E15: 131
A16: 大阪(ダイヤテック) | B16: 0 | C16: 0 | D16: 154 | E16: 0
A17: 本社取締役 | B17: 1 | C17: 0 | D17: 0 | E17: 0
A18: 多摩 | B18: 48 | C18: 25 | D18: 545 | E18: 144
A19: 本社EC | B19: 357 | C19: 332 | D19: 35 | E19: 366
A20: 北関東 | B20: 18 | C20: 10 | D20: 354 | E20: 0
A21: 本社商品開発 | B21: 6 | C21: 1 | D21: 0 | E21: 0
A22: 本社営業本部 | B22: 5 | C22: 3 | D22: 0 | E22: 0
A23: 本社購買 | B23: 42 | C23: 39 | D23: 0 | E23: 17
... A34: 合計 | B34: 7945 | C34: 6170 | D34: 43560 | E34: 41158

Sheet Report_従業員
A1: 2. 従業員別 実績
A3: 名前 | B3: 拠点 | C3: 受発注 | D3: 内線 | E3: 通話時間／秒 | F3: 外線 | G3: 通話時間／秒.1 | H3: 2025-11-01 | I3: 2025-11-02 | J3: 2025-11-03 | K3: 2025-11-04 | L3: 2025-11-05 | M3: 2025-11-06 | N3: 2025-11-07 | O3: 2025-11-08 | P3: 2025-11-09 | Q3: 2025-11-10 | R3: 2025-11-11 | S3: 2025-11-12 | T3: 2025-11-13 | U3: 2025-11-14 | V3: 2025-11-15 | W3: 2025-11-16 | X3: 2025-11-17 | Y3: 2025-11-18 | Z3: 2025-11-19 | AA3: 2025-11-20 | AB3: 2025-11-21 | AC3: 2025-11-22 | AD3: 2025-11-23 | AE3: 2025-11-24 | AF3: 2025-11-25 | AG3: 2025-11-26 | AH3: 2025-11-27 | AI3: 2025-11-28 | AJ3: 2025-11-29 | AK3: 2025-11-30 | AL3: 稼働日 | AM3: 内外線計 | AN3: 1日平均
A4: =IF(RawData_従業員!A2="","", RawData_従業員!A2) -> 中風裕司 | B4: =IF(RawData_従業員!B2="","", RawData_従業員!B2) -> 東京 | C4: =IF(RawData_従業員!C2="","", RawData_従業員!C2) | D4: =IF(RawData_従業員!D2="","", RawData_従業員!D2) -> 2 | E4: =IF(RawData_従業員!E2="","", RawData_従業員!E2) -> 49.5 | F4: =IF(RawData_従業員!F2="","", RawData_従業員!F2) -> 58 | G4: =IF(RawData_従業員!G2="","", RawData_従業員!G2) -> 53.1 | H4: =IF(RawData_従業員!H2="","", RawData_従業員!H2) -> 0 | ... AN4: =IF(RawData_従業員!AN2="","", RawData_従業員!AN2) -> 3.5
A5: =IF(RawData_従業員!A3="","", RawData_従業員!A3) -> 佐々木美咲 | B5: =IF(RawData_従業員!B3="","", RawData_従業員!B3) -> 東京 | C5: =IF(RawData_従業員!C3="","", RawData_従業員!C3) -> 受発注 | D5: =IF(RawData_従業員!D3="","", RawData_従業員!D3) -> 36 | E5: =IF(RawData_従業員!E3="","", RawData_従業員!E3) -> 48.3 | F5: =IF(RawData_従業員!F3="","", RawData_従業員!F3) -> 706 | G5: =IF(RawData_従業員!G3="","", RawData_従業員!G3) -> 60.9 | H5: =IF(RawData_従業員!H3="","", RawData_従業員!H3) -> 0 | ... AN5: =IF(RawData_従業員!AN3="","", RawData_従業員!AN3) -> 53
A6: =IF(RawData_従業員!A4="","", RawData_従業員!A4) -> 共用 | B6: =IF(RawData_従業員!B4="","", RawData_従業員!B4) -> 東京 | C6: =IF(RawData_従業員!C4="","", RawData_従業員!C4) | D6: =IF(RawData_従業員!D4="","", RawData_従業員!D4) -> 0 | E6: =IF(RawData_従業員!E4="","", RawData_従業員!E4) -> 0 | F6: =IF(RawData_従業員!F4="","", RawData_従業員!F4) -> 87 | G6: =IF(RawData_従業員!G4="","", RawData_従業員!G4) -> 81.5 | H6: =IF(RawData_従業員!H4="","", RawData_従業員!H4) -> 0 | ... AN6: =IF(RawData_従業員!AN4="","", RawData_従業員!AN4) -> 4.8
A7: =IF(RawData_従業員!A5="","", RawData_従業員!A5) -> 北林友希 | B7: =IF(RawData_従業員!B5="","", RawData_従業員!B5) -> 東京 | C7: =IF(RawData_従業員!C5="","", RawData_従業員!C5) -> 受発注 | D7: =IF(RawData_従業員!D5="","", RawData_従業員!D5) -> 72 | E7: =IF(RawData_従業員!E5="","", RawData_従業員!E5) -> 53.7 | F7: =IF(RawData_従業員!F5="","", RawData_従業員!F5) -> 1252 | G7: =IF(RawData_従業員!G5="","", RawData_従業員!G5) -> 65 | H7: =IF(RawData_従業員!H5="","", RawData_従業員!H5) -> 0 | ... AN7: =IF(RawData_従業員!AN5="","", RawData_従業員!AN5) -> 73.6
A8: =IF(RawData_従業員!A6="","", RawData_従業員!A6) -> 坂田智世 | B8: =IF(RawData_従業員!B6="","", RawData_従業員!B6) -> 東京 | C8: =IF(RawData_従業員!C6="","", RawData_従業員!C6) -> 受発注 | D8: =IF(RawData_従業員!D6="","", RawData_従業員!D6) -> 4 | E8: =IF(RawData_従業員!E6="","", RawData_従業員!E6) -> 57 | F8: =IF(RawData_従業員!F6="","", RawData_従業員!F6) -> 77 | G8: =IF(RawData_従業員!G6="","", RawData_従業員!G6) -> 69.1 | H8: =IF(RawData_従業員!H6="","", RawData_従業員!H6) -> 0 | ... AN8: =IF(RawData_従業員!AN6="","", RawData_従業員!AN6) -> 5.1
A9: =IF(RawData_従業員!A7="","", RawData_従業員!A7) -> 徳島隆廣 | B9: =IF(RawData_従業員!B7="","", RawData_従業員!B7) -> 東京 | C9: =IF(RawData_従業員!C7="","", RawData_従業員!C7) | D9: =IF(RawData_従業員!D7="","", RawData_従業員!D7) -> 2 | E9: =IF(RawData_従業員!E7="","", RawData_従業員!E7) -> 67.5 | F9: =IF(RawData_従業員!F7="","", RawData_従業員!F7) -> 11 | G9: =IF(RawData_従業員!G7="","", RawData_従業員!G7) -> 71 | H9: =IF(RawData_従業員!H7="","", RawData_従業員!H7) -> 0 | ... AN9: =IF(RawData_従業員!AN7="","", RawData_従業員!AN7) -> 1.9
A10: =IF(RawData_従業員!A8="","", RawData_従業員!A8) -> 林まど佳 | B10: =IF(RawData_従業員!B8="","", RawData_従業員!B8) -> 東京 | C10: =IF(RawData_従業員!C8="","", RawData_従業員!C8) -> 受発注 | D10: =IF(RawData_従業員!D8="","", RawData_従業員!D8) -> 93 | E10: =IF(RawData_従業員!E8="","", RawData_従業員!E8) -> 46.3 | F10: =IF(RawData_従業員!F8="","", RawData_従業員!F8) -> 1336 | G10: =IF(RawData_従業員!G8="","", RawData_従業員!G8) -> 64.6 | H10: =IF(RawData_従業員!H8="","", RawData_従業員!H8) -> 0 | ... AN10: =IF(RawData_従業員!AN8="","", RawData_従業員!AN8) -> 79.4
A11: =IF(RawData_従業員!A9="","", RawData_従業員!A9) -> 浦野鉄平 | B11: =IF(RawData_従業員!B9="","", RawData_従業員!B9) -> 東京 | C11: =IF(RawData_従業員!C9="","", RawData_従業員!C9) | D11: =IF(RawData_従業員!D9="","", RawData_従業員!D9) -> 7 | E11: =IF(RawData_従業員!E9="","", RawData_従業員!E9) -> 53.3 | F11: =IF(RawData_従業員!F9="","", RawData_従業員!F9) -> 23 | G11: =IF(RawData_従業員!G9="","", RawData_従業員!G9) -> 56.5 | H11: =IF(RawData_従業員!H9="","", RawData_従業員!H9) -> 0 | ... AN11: =IF(RawData_従業員!AN9="","", RawData_従業員!AN9) -> 2.5
A12: =IF(RawData_従業員!A10="","", RawData_従業員!A10) -> 片桐芳夫 | B12: =IF(RawData_従業員!B10="","", RawData_従業員!B10) -> 東京 | C12: =IF(RawData_従業員!C10="","", RawData_従業員!C10) | D12: =IF(RawData_従業員!D10="","", RawData_従業員!D10) -> 7 | E12: =IF(RawData_従業員!E10="","", RawData_従業員!E10) -> 32.6 | F12: =IF(RawData_従業員!F10="","", RawData_従業員!F10) -> 119 | G12: =IF(RawData_従業員!G10="","", RawData_従業員!G10) -> 33.6 | H12: =IF(RawData_従業員!H10="","", RawData_従業員!H10) -> 1 | ... AN12: =IF(RawData_従業員!AN10="","", RawData_従業員!AN10) -> 5.7
A13: =IF(RawData_従業員!A11="","", RawData_従業員!A11) -> 玉川圭介 | B13: =IF(RawData_従業員!B11="","", RawData_従業員!B11) -> 東京 | C13: =IF(RawData_従業員!C11="","", RawData_従業員!C11) | D13: =IF(RawData_従業員!D11="","", RawData_従業員!D11) -> 2 | E13: =IF(RawData_従業員!E11="","", RawData_従業員!E11) -> 24 | F13: =IF(RawData_従業員!F11="","", RawData_従業員!F11) -> 38 | G13: =IF(RawData_従業員!G11="","", RawData_従業員!G11) -> 67.6 | H13: =IF(RawData_従業員!H11="","", RawData_従業員!H11) -> 0 | ... AN13: =IF(RawData_従業員!AN11="","", RawData_従業員!AN11) -> 2.7
A14: =IF(RawData_従業員!A12="","", RawData_従業員!A12) -> 田邉七海 | B14: =IF(RawData_従業員!B12="","", RawData_従業員!B12) -> 東京 | C14: =IF(RawData_従業員!C12="","", RawData_従業員!C12) | D14: =IF(RawData_従業員!D12="","", RawData_従業員!D12) -> 0 | E14: =IF(RawData_従業員!E12="","", RawData_従業員!E12) -> 0 | F14: =IF(RawData_従業員!F12="","", RawData_従業員!F12) -> 1 | G14: =IF(RawData_従業員!G12="","", RawData_従業員!G12) -> 53 | H14: =IF(RawData_従業員!H12="","", RawData_従業員!H12) -> 0 | ... AN14: =IF(RawData_従業員!AN12="","", RawData_従業員!AN12) -> 1
A15: =IF(RawData_従業員!A13="","", RawData_従業員!A13) -> 西垣彩 | B15: =IF(RawData_従業員!B13="","", RawData_従業員!B13) -> 東京 | C15: =IF(RawData_従業員!C13="","", RawData_従業員!C13) -> 受発注 | D15: =IF(RawData_従業員!D13="","", RawData_従業員!D13) -> 81 | E15: =IF(RawData_従業員!E13="","", RawData_従業員!E13) -> 54 | F15: =IF(RawData_従業員!F13="","", RawData_従業員!F13) -> 1236 | G15: =IF(RawData_従業員!G13="","", RawData_従業員!G13) -> 61.7 | H15: =IF(RawData_従業員!H13="","", RawData_従業員!H13) -> 0 | ... AN15: =IF(RawData_従業員!AN13="","", RawData_従業員!AN13) -> 77.5
... A53: =IF(RawData_従業員!A51="","", RawData_従業員!A51) -> 平野翔大 | B53: =IF(RawData_従業員!B51="","", RawData_従業員!B51) -> 千葉 | C53: =IF(RawData_従業員!C51="","", RawData_従業員!C51) | D53: =IF(RawData_従業員!D51="","", RawData_従業員!D51) -> 20 | E53: =IF(RawData_従業員!E51="","", RawData_従業員!E51) -> 52.7 | F53: =IF(RawData_従業員!F51="","", RawData_従業員!F51) -> 89 | G53: =IF(RawData_従業員!G51="","", RawData_従業員!G51) -> 60.9 | H53: =IF(RawData_従業員!H51="","", RawData_従業員!H51) -> 0 | ... AN53: =IF(RawData_従業員!AN51="","", RawData_従業員!AN51) -> 9.1

Sheet RawData_従業員
A1: 名前 | B1: 拠点 | C1: 受発注 | D1: 内線 | E1: 通話時間／秒 | F1: 外線 | G1: 通話時間／秒.1 | H1: 2025-11-01 | I1: 2025-11-02 | J1: 2025-11-03 | K1: 2025-11-04 | L1: 2025-11-05 | M1: 2025-11-06 | N1: 2025-11-07 | O1: 2025-11-08 | P1: 2025-11-09 | Q1: 2025-11-10 | R1: 2025-11-11 | S1: 2025-11-12 | T1: 2025-11-13 | U1: 2025-11-14 | V1: 2025-11-15 | W1: 2025-11-16 | X1: 2025-11-17 | Y1: 2025-11-18 | Z1: 2025-11-19 | AA1: 2025-11-20 | AB1: 2025-11-21 | AC1: 2025-11-22 | AD1: 2025-11-23 | AE1: 2025-11-24 | AF1: 2025-11-25 | AG1: 2025-11-26 | AH1: 2025-11-27 | AI1: 2025-11-28 | AJ1: 2025-11-29 | AK1: 2025-11-30 | AL1: 稼働日 | AM1: 内外線計 | AN1: 1日平均
A2: 中風裕司 | B2: 東京 | D2: 2 | E2: 49.5 | F2: 58 | G2: 53.1 | H2: 0 | I2: 0 | J2: 0 | K2: 2 | L2: 3 | M2: 4 | N2: 8 | O2: 0 | P2: 0 | Q2: 8 | R2: 2 | S2: 0 | T2: 4 | U2: 2 | V2: 0 | W2: 0 | X2: 2 | Y2: 3 | Z2: 1 | AA2: 1 | AB2: 4 | AC2: 0 | AD2: 0 | AE2: 0 | AF2: 7 | AG2: 4 | AH2: 2 | AI2: 3 | AJ2: 0 | AK2: 0 | AL2: 17 | AM2: 60 | AN2: 3.5
A3: 佐々木美咲 | B3: 東京 | C3: 受発注 | D3: 36 | E3: 48.3 | F3: 706 | G3: 60.9 | H3: 0 | I3: 0 | J3: 0 | K3: 39 | L3: 49 | M3: 69 | N3: 48 | O3: 0 | P3: 0 | Q3: 38 | R3: 58 | S3: 59 | T3: 58 | U3: 40 | V3: 0 | W3: 0 | X3: 61 | Y3: 72 | Z3: 48 | AA3: 57 | AB3: 46 | AC3: 0 | AD3: 0 | AE3: 0 | AF3: 0 | AG3: 0 | AH3: 0 | AI3: 0 | AJ3: 0 | AK3: 0 | AL3: 14 | AM3: 742 | AN3: 53
A4: 共用 | B4: 東京 | D4: 0 | E4: 0 | F4: 87 | G4: 81.5 | H4: 0 | I4: 0 | J4: 0 | K4: 6 | L4: 5 | M4: 6 | N4: 7 | O4: 0 | P4: 0 | Q4: 2 | R4: 3 | S4: 8 | T4: 1 | U4: 3 | V4: 0 | W4: 0 | X4: 2 | Y4: 7 | Z4: 6 | AA4: 5 | AB4: 6 | AC4: 0 | AD4: 0 | AE4: 0 | AF4: 5 | AG4: 6 | AH4: 4 | AI4: 5 | AJ4: 0 | AK4: 0 | AL4: 18 | AM4: 87 | AN4: 4.8
A5: 北林友希 | B5: 東京 | C5: 受発注 | D5: 72 | E5: 53.7 | F5: 1252 | G5: 65 | H5: 0 | I5: 0 | J5: 0 | K5: 90 | L5: 99 | M5: 78 | N5: 60 | O5: 0 | P5: 0 | Q5: 63 | R5: 83 | S5: 71 | T5: 70 | U5: 74 | V5: 0 | W5: 0 | X5: 69 | Y5: 74 | Z5: 56 | AA5: 58 | AB5: 68 | AC5: 0 | AD5: 0 | AE5: 0 | AF5: 78 | AG5: 94 | AH5: 74 | AI5: 65 | AJ5: 0 | AK5: 0 | AL5: 18 | AM5: 1324 | AN5: 73.6
A6: 坂田智世 | B6: 東京 | C6: 受発注 | D6: 4 | E6: 57 | F6: 77 | G6: 69.1 | H6: 0 | I6: 0 | J6: 0 | K6: 7 | L6: 8 | M6: 5 | N6: 2 | O6: 0 | P6: 0 | Q6: 2 | R6: 3 | S6: 1 | T6: 1 | U6: 2 | V6: 0 | W6: 0 | X6: 1 | Y6: 17 | Z6: 1 | AA6: 0 | AB6: 0 | AC6: 0 | AD6: 0 | AE6: 0 | AF6: 9 | AG6: 10 | AH6: 4 | AI6: 8 | AJ6: 0 | AK6: 0 | AL6: 16 | AM6: 81 | AN6: 5.1
A7: 徳島隆廣 | B7: 東京 | D7: 2 | E7: 67.5 | F7: 11 | G7: 71 | H7: 0 | I7: 0 | J7: 0 | K7: 2 | L7: 2 | M7: 0 | N7: 2 | O7: 0 | P7: 0 | Q7: 0 | R7: 1 | S7: 1 | T7: 0 | U7: 0 | V7: 0 | W7: 0 | X7: 0 | Y7: 0 | Z7: 0 | AA7: 2 | AB7: 3 | AC7: 0 | AD7: 0 | AE7: 0 | AF7: 0 | AG7: 0 | AH7: 0 | AI7: 0 | AJ7: 0 | AK7: 0 | AL7: 7 | AM7: 13 | AN7: 1.9
A8: 林まど佳 | B8: 東京 | C8: 受発注 | D8: 93 | E8: 46.3 | F8: 1336 | G8: 64.6 | H8: 0 | I8: 0 | J8: 0 | K8: 89 | L8: 77 | M8: 80 | N8: 79 | O8: 0 | P8: 0 | Q8: 80 | R8: 76 | S8: 87 | T8: 86 | U8: 86 | V8: 0 | W8: 0 | X8: 83 | Y8: 80 | Z8: 66 | AA8: 83 | AB8: 63 | AC8: 0 | AD8: 0 | AE8: 0 | AF8: 76 | AG8: 78 | AH8: 66 | AI8: 94 | AJ8: 0 | AK8: 0 | AL8: 18 | AM8: 1429 | AN8: 79.4
A9: 浦野鉄平 | B9: 東京 | D9: 7 | E9: 53.3 | F9: 23 | G9: 56.5 | H9: 0 | I9: 0 | J9: 0 | K9: 3 | L9: 1 | M9: 0 | N9: 3 | O9: 0 | P9: 0 | Q9: 1 | R9: 0 | S9: 2 | T9: 1 | U9: 0 | V9: 0 | W9: 0 | X9: 2 | Y9: 4 | Z9: 0 | AA9: 0 | AB9: 2 | AC9: 0 | AD9: 0 | AE9: 0 | AF9: 1 | AG9: 0 | AH9: 4 | AI9: 6 | AJ9: 0 | AK9: 0 | AL9: 12 | AM9: 30 | AN9: 2.5
A10: 片桐芳夫 | B10: 東京 | D10: 7 | E10: 32.6 | F10: 119 | G10: 33.6 | H10: 1 | I10: 0 | J10: 0 | K10: 8 | L10: 8 | M10: 8 | N10: 7 | O10: 1 | P10: 0 | Q10: 6 | R10: 4 | S10: 8 | T10: 3 | U10: 4 | V10: 1 | W10: 0 | X10: 5 | Y10: 5 | Z10: 8 | AA10: 9 | AB10: 9 | AC10: 0 | AD10: 0 | AE10: 0 | AF10: 8 | AG10: 5 | AH10: 7 | AI10: 7 | AJ10: 4 | AK10: 0 | AL10: 22 | AM10: 126 | AN10: 5.7
A11: 玉川圭介 | B11: 東京 | D11: 2 | E11: 24 | F11: 38 | G11: 67.6 | H11: 0 | I11: 0 | J11: 0 | K11: 6 | L11: 2 | M11: 4 | N11: 4 | O11: 0 | P11: 0 | Q11: 4 | R11: 1 | S11: 3 | T11: 2 | U11: 2 | V11: 0 | W11: 0 | X11: 0 | Y11: 0 | Z11: 3 | AA11: 3 | AB11: 1 | AC11: 0 | AD11: 0 | AE11: 0 | AF11: 2 | AG11: 2 | AH11: 1 | AI11: 0 | AJ11: 0 | AK11: 0 | AL11: 15 | AM11: 40 | AN11: 2.7
A12: 田邉七海 | B12: 東京 | D12: 0 | E12: 0 | F12: 1 | G12: 53 | H12: 0 | I12: 0 | J12: 0 | K12: 0 | L12: 0 | M12: 0 | N12: 0 | O12: 0 | P12: 0 | Q12: 0 | R12: 0 | S12: 0 | T12: 0 | U12: 0 | V12: 0 | W12: 0 | X12: 0 | Y12: 0 | Z12: 0 | AA12: 0 | AB12: 0 | AC12: 0 | AD12: 0 | AE12: 0 | AF12: 0 | AG12: 1 | AH12: 0 | AI12: 0 | AJ12: 0 | AK12: 0 | AL12: 1 | AM12: 1 | AN12: 1
A13: 西垣彩 | B13: 東京 | C13: 受発注 | D13: 81 | E13: 54 | F13: 1236 | G13: 61.7 | H13: 0 | I13: 0 | J13: 0 | K13: 81 | L13: 97 | M13: 87 | N13: 60 | O13: 0 | P13: 0 | Q13: 80 | R13: 73 | S13: 84 | T13: 67 | U13: 57 | V13: 0 | W13: 0 | X13: 79 | Y13: 0 | Z13: 71 | AA13: 70 | AB13: 85 | AC13: 0 | AD13: 0 | AE13: 0 | AF13: 92 | AG13: 81 | AH13: 77 | AI13: 76 | AJ13: 0 | AK13: 0 | AL13: 17 | AM13: 1317 | AN13: 77.5
A14: 豊島亮 | B14: 東京 | D14: 2 | E14: 68.5 | F14: 83 | G14: 65.2 | H14: 0 | I14: 0 | J14: 0 | K14: 8 | L14: 4 | M14: 2 | N14: 2 | O14: 0 | P14: 0 | Q14: 12 | R14: 5 | S14: 3 | T14: 5 | U14: 3 | V14: 0 | W14: 0 | X14: 1 | Y14: 8 | Z14: 4 | AA14: 2 | AB14: 5 | AC14: 0 | AD14: 0 | AE14: 0 | AF14: 4 | AG14: 1 | AH14: 10 | AI14: 6 | AJ14: 0 | AK14: 0 | AL14: 18 | AM14: 85 | AN14: 4.7
A15: 高澤早紀 | B15: 東京 | C15: 受発注 | D15: 58 | E15: 62.7 | F15: 724 | G15: 67.5 | H15: 0 | I15: 0 | J15: 0 | K15: 22 | L15: 17 | M15: 8 | N15: 42 | O15: 0 | P15: 0 | Q15: 42 | R15: 56 | S15: 19 | T15: 45 | U15: 35 | V15: 0 | W15: 0 | X15: 49 | Y15: 65 | Z15: 36 | AA15: 45 | AB15: 47 | AC15: 0 | AD15: 0 | AE15: 0 | AF15: 73 | AG15: 80 | AH15: 67 | AI15: 34 | AJ15: 0 | AK15: 0 | AL15: 18 | AM15: 782 | AN15: 43.4
A16: 中山満里奈 | B16: 横浜 | C16: 受発注 | D16: 77 | E16: 64.4 | F16: 947 | G16: 75.4 | H16: 0 | I16: 0 | J16: 0 | K16: 77 | L16: 76 | M16: 74 | N16: 62 | O16: 0 | P16: 0 | Q16: 56 | R16: 58 | S16: 59 | T16: 49 | U16: 50 | V16: 0 | W16: 0 | X16: 59 | Y16: 38 | Z16: 72 | AA16: 40 | AB16: 67 | AC16: 0 | AD16: 0 | AE16: 0 | AF16: 65 | AG16: 0 | AH16: 66 | AI16: 56 | AJ16: 0 | AK16: 0 | AL16: 17 | AM16: 1024 | AN16: 60.2
A17: 吉田玲 | B17: 横浜 | D17: 43 | E17: 56.8 | F17: 857 | G17: 78.5 | H17: 0 | I17: 0 | J17: 0 | K17: 60 | L17: 42 | M17: 26 | N17: 67 | O17: 0 | P17: 0 | Q17: 60 | R17: 48 | S17: 55 | T17: 63 | U17: 62 | V17: 0 | W17: 0 | X17: 30 | Y17: 54 | Z17: 52 | AA17: 46 | AB17: 57 | AC17: 0 | AD17: 0 | AE17: 0 | AF17: 63 | AG17: 61 | AH17: 25 | AI17: 29 | AJ17: 0 | AK17: 0 | AL17: 18 | AM17: 900 | AN17: 50
A18: 奥秋素子 | B18: 横浜 | C18: 受発注 | D18: 32 | E18: 53.9 | F18: 872 | G18: 76.5 | H18: 0 | I18: 0 | J18: 0 | K18: 43 | L18: 37 | M18: 20 | N18: 50 | O18: 0 | P18: 0 | Q18: 46 | R18: 59 | S18: 47 | T18: 52 | U18: 78 | V18: 0 | W18: 0 | X18: 54 | Y18: 49 | Z18: 54 | AA18: 50 | AB18: 79 | AC18: 0 | AD18: 0 | AE18: 0 | AF18: 48 | AG18: 51 | AH18: 51 | AI18: 36 | AJ18: 0 | AK18: 0 | AL18: 18 | AM18: 904 | AN18: 50.2
A19: 山﨑啓右 | B19: 横浜 | C19: 受発注 | D19: 35 | E19: 77.5 | F19: 732 | G19: 95.5 | H19: 0 | I19: 0 | J19: 0 | K19: 38 | L19: 48 | M19: 51 | N19: 32 | O19: 0 | P19: 0 | Q19: 48 | R19: 46 | S19: 53 | T19: 35 | U19: 47 | V19: 0 | W19: 0 | X19: 43 | Y19: 31 | Z19: 37 | AA19: 45 | AB19: 47 | AC19: 0 | AD19: 0 | AE19: 0 | AF19: 44 | AG19: 32 | AH19: 40 | AI19: 50 | AJ19: 0 | AK19: 0 | AL19: 18 | AM19: 767 | AN19: 42.6
A20: 川崎光弘 | B20: 横浜 | D20: 1 | E20: 22 | F20: 2 | G20: 66 | H20: 0 | I20: 0 | J20: 0 | K20: 0 | L20: 2 | M20: 0 | N20: 0 | O20: 0 | P20: 0 | Q20: 0 | R20: 0 | S20: 0 | T20: 0 | U20: 0 | V20: 0 | W20: 0 | X20: 0 | Y20: 1 | Z20: 0 | AA20: 0 | AB20: 0 | AC20: 0 | AD20: 0 | AE20: 0 | AF20: 0 | AG20: 0 | AH20: 0 | AI20: 0 | AJ20: 0 | AK20: 0 | AL20: 2 | AM20: 3 | AN20: 1.5
A21: 川崎瞳 | B21: 横浜 | C21: 受発注 | D21: 75 | E21: 134.5 | F21: 184 | G21: 85.7 | H21: 0 | I21: 0 | J21: 0 | K21: 21 | L21: 7 | M21: 14 | N21: 12 | O21: 0 | P21: 0 | Q21: 10 | R21: 12 | S21: 20 | T21: 12 | U21: 28 | V21: 0 | W21: 0 | X21: 19 | Y21: 9 | Z21: 5 | AA21: 9 | AB21: 16 | AC21: 0 | AD21: 0 | AE21: 0 | AF21: 23 | AG21: 11 | AH21: 14 | AI21: 17 | AJ21: 0 | AK21: 0 | AL21: 18 | AM21: 259 | AN21: 14.4
A22: 横内敦 | B22: 横浜 | D22: 2 | E22: 121 | F22: 14 | G22: 79.3 | H22: 0 | I22: 0 | J22: 0 | K22: 0 | L22: 0 | M22: 1 | N22: 0 | O22: 0 | P22: 0 | Q22: 1 | R22: 0 | S22: 0 | T22: 0 | U22: 0 | V22: 0 | W22: 0 | X22: 0 | Y22: 0 | Z22: 0 | AA22: 4 | AB22: 0 | AC22: 0 | AD22: 0 | AE22: 0 | AF22: 2 | AG22: 0 | AH22: 0 | AI22: 8 | AJ22: 0 | AK22: 0 | AL22: 5 | AM22: 16 | AN22: 3.2
A23: 田鹿僚志 | B23: 横浜 | D23: 3 | E23: 154 | F23: 40 | G23: 64.9 | H23: 0 | I23: 0 | J23: 0 | K23: 43 | L23: 0 | M23: 0 | N23: 0 | O23: 0 | P23: 0 | Q23: 0 | R23: 0 | S23: 0 | T23: 0 | U23: 0 | V23: 0 | W23: 0 | X23: 0 | Y23: 0 | Z23: 0 | AA23: 0 | AB23: 0 | AC23: 0 | AD23: 0 | AE23: 0 | AF23: 0 | AG23: 0 | AH23: 0 | AI23: 0 | AJ23: 0 | AK23: 0 | AL23: 1 | AM23: 43 | AN23: 43
A24: 笹生義満 | B24: 横浜 | D24: 0 | E24: 0 | F24: 1 | G24: 63 | H24: 0 | I24: 0 | J24: 0 | K24: 0 | L24: 0 | M24: 0 | N24: 0 | O24: 0 | P24: 0 | Q24: 0 | R24: 0 | S24: 0 | T24: 0 | U24: 0 | V24: 0 | W24: 0 | X24: 0 | Y24: 0 | Z24: 0 | AA24: 0 | AB24: 0 | AC24: 0 | AD24: 0 | AE24: 0 | AF24: 1 | AG24: 0 | AH24: 0 | AI24: 0 | AJ24: 0 | AK24: 0 | AL24: 1 | AM24: 1 | AN24: 1
A25: 舞智江 | B25: 横浜 | C25: 受発注 | D25: 71 | E25: 69 | F25: 1024 | G25: 81.2 | H25: 0 | I25: 0 | J25: 0 | K25: 43 | L25: 46 | M25: 57 | N25: 69 | O25: 0 | P25: 0 | Q25: 88 | R25: 72 | S25: 44 | T25: 59 | U25: 0 | V25: 0 | W25: 0 | X25: 80 | Y25: 55 | Z25: 84 | AA25: 89 | AB25: 53 | AC25: 0 | AD25: 0 | AE25: 0 | AF25: 78 | AG25: 79 | AH25: 27 | AI25: 72 | AJ25: 0 | AK25: 0 | AL25: 17 | AM25: 1095 | AN25: 64.4
A26: 萩原直美 | B26: 横浜 | C26: 受発注 | D26: 59 | E26: 82.7 | F26: 908 | G26: 80.8 | H26: 0 | I26: 0 | J26: 0 | K26: 75 | L26: 61 | M26: 89 | N26: 46 | O26: 0 | P26: 0 | Q26: 17 | R26: 36 | S26: 50 | T26: 51 | U26: 52 | V26: 0 | W26: 0 | X26: 35 | Y26: 36 | Z26: 17 | AA26: 70 | AB26: 58 | AC26: 0 | AD26: 0 | AE26: 0 | AF26: 52 | AG26: 51 | AH26: 98 | AI26: 73 | AJ26: 0 | AK26: 0 | AL26: 18 | AM26: 967 | AN26: 53.7
A27: 青木観奈 | B27: 横浜 | C27: 受発注 | D27: 27 | E27: 79.6 | F27: 1054 | G27: 86.1 | H27: 0 | I27: 0 | J27: 0 | K27: 37 | L27: 69 | M27: 91 | N27: 77 | O27: 0 | P27: 0 | Q27: 67 | R27: 66 | S27: 63 | T27: 53 | U27: 64 | V27: 0 | W27: 0 | X27: 67 | Y27: 51 | Z27: 57 | AA27: 50 | AB27: 0 | AC27: 0 | AD27: 0 | AE27: 0 | AF27: 32 | AG27: 81 | AH27: 80 | AI27: 76 | AJ27: 0 | AK27: 0 | AL27: 17 | AM27: 1081 | AN27: 63.6
A28: 久保貴志 | B28: 埼玉 | D28: 4 | E28: 61.5 | F28: 91 | G28: 43.5 | H28: 0 | I28: 0 | J28: 0 | K28: 4 | L28: 3 | M28: 3 | N28: 3 | O28: 0 | P28: 0 | Q28: 4 | R28: 5 | S28: 3 | T28: 1 | U28: 5 | V28: 0 | W28: 0 | X28: 4 | Y28: 5 | Z28: 4 | AA28: 8 | AB28: 5 | AC28: 0 | AD28: 0 | AE28: 0 | AF28: 3 | AG28: 5 | AH28: 4 | AI28: 26 | AJ28: 0 | AK28: 0 | AL28: 18 | AM28: 95 | AN28: 5.3
A29: 池田千恵子 | B29: 埼玉 | C29: 受発注 | D29: 31 | E29: 73.2 | F29: 628 | G29: 83.8 | H29: 0 | I29: 0 | J29: 0 | K29: 7 | L29: 1 | M29: 3 | N29: 31 | O29: 0 | P29: 0 | Q29: 37 | R29: 47 | S29: 33 | T29: 42 | U29: 44 | V29: 0 | W29: 0 | X29: 42 | Y29: 39 | Z29: 50 | AA29: 48 | AB29: 37 | AC29: 0 | AD29: 0 | AE29: 0 | AF29: 39 | AG29: 49 | AH29: 47 | AI29: 63 | AJ29: 0 | AK29: 0 | AL29: 18 | AM29: 659 | AN29: 36.6
A30: 田邉裕介 | B30: 埼玉 | D30: 4 | E30: 129.5 | F30: 25 | G30: 69.8 | H30: 0 | I30: 0 | J30: 0 | K30: 3 | L30: 1 | M30: 4 | N30: 2 | O30: 0 | P30: 0 | Q30: 1 | R30: 0 | S30: 1 | T30: 0 | U30: 0 | V30: 0 | W30: 0 | X30: 0 | Y30: 0 | Z30: 0 | AA30: 2 | AB30: 2 | AC30: 0 | AD30: 0 | AE30: 0 | AF30: 3 | AG30: 0 | AH30: 1 | AI30: 9 | AJ30: 0 | AK30: 0 | AL30: 11 | AM30: 29 | AN30: 2.6
A31: 矢島静音 | B31: 埼玉 | C31: 受発注 | D31: 8 | E31: 79.4 | F31: 627 | G31: 98.2 | H31: 0 | I31: 0 | J31: 0 | K31: 53 | L31: 53 | M31: 0 | N31: 0 | O31: 0 | P31: 0 | Q31: 50 | R31: 37 | S31: 64 | T31: 40 | U31: 44 | V31: 0 | W31: 0 | X31: 30 | Y31: 0 | Z31: 0 | AA31: 31 | AB31: 46 | AC31: 0 | AD31: 0 | AE31: 0 | AF31: 47 | AG31: 38 | AH31: 59 | AI31: 43 | AJ31: 0 | AK31: 0 | AL31: 14 | AM31: 635 | AN31: 45.4
A32: 石川恵理 | B32: 埼玉 | C32: 受発注 | D32: 46 | E32: 60.6 | F32: 986 | G32: 64.4 | H32: 0 | I32: 0 | J32: 0 | K32: 67 | L32: 66 | M32: 72 | N32: 68 | O32: 0 | P32: 0 | Q32: 63 | R32: 52 | S32: 63 | T32: 78 | U32: 0 | V32: 0 | W32: 0 | X32: 54 | Y32: 60 | Z32: 76 | AA32: 43 | AB32: 55 | AC32: 0 | AD32: 0 | AE32: 0 | AF32: 56 | AG32: 44 | AH32: 49 | AI32: 66 | AJ32: 0 | AK32: 0 | AL32: 17 | AM32: 1032 | AN32: 60.7
A33: 竹内梓 | B33: 埼玉 | C33: 受発注 | D33: 23 | E33: 85.7 | F33: 683 | G33: 106.2 | H33: 0 | I33: 0 | J33: 0 | K33: 25 | L33: 35 | M33: 47 | N33: 48 | O33: 0 | P33: 0 | Q33: 24 | R33: 48 | S33: 27 | T33: 22 | U33: 39 | V33: 0 | W33: 0 | X33: 35 | Y33: 44 | Z33: 44 | AA33: 41 | AB33: 43 | AC33: 0 | AD33: 0 | AE33: 0 | AF33: 45 | AG33: 44 | AH33: 40 | AI33: 55 | AJ33: 0 | AK33: 0 | AL33: 18 | AM33: 706 | AN33: 39.2
A34: 篠宮寛織 | B34: 埼玉 | D34: 1 | E34: 40 | F34: 30 | G34: 63.6 | H34: 0 | I34: 0 | J34: 0 | K34: 4 | L34: 2 | M34: 5 | N34: 0 | O34: 0 | P34: 0 | Q34: 2 | R34: 1 | S34: 2 | T34: 1 | U34: 0 | V34: 0 | W34: 0 | X34: 1 | Y34: 1 | Z34: 2 | AA34: 0 | AB34: 1 | AC34: 0 | AD34: 0 | AE34: 0 | AF34: 1 | AG34: 1 | AH34: 7 | AI34: 0 | AJ34: 0 | AK34: 0 | AL34: 14 | AM34: 31 | AN34: 2.2
A35: 細田昌子 | B35: 埼玉 | C35: 受発注 | D35: 108 | E35: 117.3 | F35: 813 | G35: 81.1 | H35: 0 | I35: 0 | J35: 0 | K35: 72 | L35: 77 | M35: 88 | N35: 64 | O35: 0 | P35: 0 | Q35: 43 | R35: 45 | S35: 57 | T35: 50 | U35: 66 | V35: 0 | W35: 0 | X35: 54 | Y35: 66 | Z35: 47 | AA35: 34 | AB35: 49 | AC35: 0 | AD35: 0 | AE35: 0 | AF35: 59 | AG35: 50 | AH35: 0 | AI35: 0 | AJ35: 0 | AK35: 0 | AL35: 16 | AM35: 921 | AN35: 57.6
A36: 豊田里花 | B36: 埼玉 | C36: 受発注 | D36: 34 | E36: 43.8 | F36: 986 | G36: 69.3 | H36: 0 | I36: 0 | J36: 0 | K36: 58 | L36: 61 | M36: 66 | N36: 65 | O36: 0 | P36: 0 | Q36: 60 | R36: 40 | S36: 52 | T36: 55 | U36: 75 | V36: 0 | W36: 0 | X36: 86 | Y36: 67 | Z36: 52 | AA36: 50 | AB36: 58 | AC36: 0 | AD36: 0 | AE36: 0 | AF36: 68 | AG36: 48 | AH36: 59 | AI36: 0 | AJ36: 0 | AK36: 0 | AL36: 17 | AM36: 1020 | AN36: 60
A37: 金子友希 | B37: 埼玉 | C37: 受発注 | D37: 64 | E37: 65.1 | F37: 698 | G37: 73.6 | H37: 0 | I37: 0 | J37: 0 | K37: 46 | L37: 55 | M37: 66 | N37: 62 | O37: 0 | P37: 0 | Q37: 37 | R37: 37 | S37: 32 | T37: 32 | U37: 43 | V37: 0 | W37: 0 | X37: 36 | Y37: 35 | Z37: 40 | AA37: 30 | AB37: 25 | AC37: 0 | AD37: 0 | AE37: 0 | AF37: 42 | AG37: 44 | AH37: 40 | AI37: 60 | AJ37: 0 | AK37: 0 | AL37: 18 | AM37: 762 | AN37: 42.3
A38: 関野和彦 | B38: 埼玉 | D38: 1 | E38: 124 | F38: 30 | G38: 114.6 | H38: 0 | I38: 0 | J38: 0 | K38: 2 | L38: 0 | M38: 5 | N38: 3 | O38: 0 | P38: 0 | Q38: 3 | R38: 2 | S38: 2 | T38: 0 | U38: 3 | V38: 0 | W38: 0 | X38: 0 | Y38: 0 | Z38: 3 | AA38: 1 | AB38: 0 | AC38: 0 | AD38: 0 | AE38: 0 | AF38: 1 | AG38: 1 | AH38: 1 | AI38: 4 | AJ38: 0 | AK38: 0 | AL38: 13 | AM38: 31 | AN38: 2.4
A39: 北出智子 | B39: 滋賀 | C39: 受発注 | D39: 32 | E39: 122.8 | F39: 145 | G39: 81.2 | H39: 0 | I39: 0 | J39: 0 | K39: 7 | L39: 7 | M39: 13 | N39: 6 | O39: 0 | P39: 0 | Q39: 5 | R39: 9 | S39: 15 | T39: 7 | U39: 13 | V39: 0 | W39: 0 | X39: 12 | Y39: 14 | Z39: 7 | AA39: 3 | AB39: 10 | AC39: 0 | AD39: 0 | AE39: 0 | AF39: 20 | AG39: 13 | AH39: 9 | AI39: 7 | AJ39: 0 | AK39: 0 | AL39: 18 | AM39: 177 | AN39: 9.8
A40: 松井治美 | B40: 滋賀 | C40: 受発注 | D40: 22 | E40: 69.8 | F40: 427 | G40: 81.9 | H40: 0 | I40: 0 | J40: 0 | K40: 27 | L40: 21 | M40: 30 | N40: 36 | O40: 0 | P40: 0 | Q40: 24 | R40: 24 | S40: 18 | T40: 33 | U40: 20 | V40: 0 | W40: 0 | X40: 21 | Y40: 24 | Z40: 30 | AA40: 26 | AB40: 14 | AC40: 0 | AD40: 0 | AE40: 0 | AF40: 26 | AG40: 27 | AH40: 26 | AI40: 22 | AJ40: 0 | AK40: 0 | AL40: 18 | AM40: 449 | AN40: 24.9
...

Sheet Report_関数拠点
A1: 3. 拠点別 関数集計
A3: 拠点名 | B3: 2025年11月から外線のみ | C3: 外線のみ | D3: 人員 | E3: 1人当たり／月 | F3: 全体からの比率
A4: =IF(RawData_関数拠点!A2="","", RawData_関数拠点!A2) -> 東京 | B4: =IF(RawData_関数拠点!B2="","", RawData_関数拠点!B2) -> 5751 | C4: =IF(RawData_関数拠点!C2="","", RawData_関数拠点!C2) -> 205.4 | D4: =IF(RawData_関数拠点!D2="","", RawData_関数拠点!D2) -> 14 | E4: =IF(RawData_関数拠点!E2="","", RawData_関数拠点!E2) -> 410.8 | F4: =IF(RawData_関数拠点!F2="","", RawData_関数拠点!F2) -> 0.13972982
A5: =IF(RawData_関数拠点!A3="","", RawData_関数拠点!A3) -> 横浜 | B5: =IF(RawData_関数拠点!B3="","", RawData_関数拠点!B3) -> 6635 | C5: =IF(RawData_関数拠点!C3="","", RawData_関数拠点!C3) -> 237 | D5: =IF(RawData_関数拠点!D3="","", RawData_関数拠点!D3) -> 12 | E5: =IF(RawData_関数拠点!E3="","", RawData_関数拠点!E3) -> 552.9 | F5: =IF(RawData_関数拠点!F3="","", RawData_関数拠点!F3) -> 0.16120803
A6: =IF(RawData_関数拠点!A4="","", RawData_関数拠点!A4) -> 埼玉 | B6: =IF(RawData_関数拠点!B4="","", RawData_関数拠点!B4) -> 5597 | C6: =IF(RawData_関数拠点!C4="","", RawData_関数拠点!C4) -> 199.9 | D6: =IF(RawData_関数拠点!D4="","", RawData_関数拠点!D4) -> 11 | E6: =IF(RawData_関数拠点!E4="","", RawData_関数拠点!E4) -> 508.8 | F6: =IF(RawData_関数拠点!F4="","", RawData_関数拠点!F4) -> 0.13598814
A7: =IF(RawData_関数拠点!A5="","", RawData_関数拠点!A5) -> 滋賀 | B7: =IF(RawData_関数拠点!B5="","", RawData_関数拠点!B5) -> 1773 | C7: =IF(RawData_関数拠点!C5="","", RawData_関数拠点!C5) -> 63.3 | D7: =IF(RawData_関数拠点!D5="","", RawData_関数拠点!D5) -> 4 | E7: =IF(RawData_関数拠点!E5="","", RawData_関数拠点!E5) -> 443.3 | F7: =IF(RawData_関数拠点!F5="","", RawData_関数拠点!F5) -> 0.043077895
A8: =IF(RawData_関数拠点!A6="","", RawData_関数拠点!A6) -> 大阪 | B8: =IF(RawData_関数拠点!B6="","", RawData_関数拠点!B6) -> 212 | C8: =IF(RawData_関数拠点!C6="","", RawData_関数拠点!C6) -> 7.6 | D8: =IF(RawData_関数拠点!D6="","", RawData_関数拠点!D6) -> 6 | E8: =IF(RawData_関数拠点!E6="","", RawData_関数拠点!E6) -> 35.3 | F8: =IF(RawData_関数拠点!F6="","", RawData_関数拠点!F6) -> 0.005150882
A9: =IF(RawData_関数拠点!A7="","", RawData_関数拠点!A7) -> 千葉 | B9: =IF(RawData_関数拠点!B7="","", RawData_関数拠点!B7) -> 1551 | C9: =IF(RawData_関数拠点!C7="","", RawData_関数拠点!C7) -> 55.4 | D9: =IF(RawData_関数拠点!D7="","", RawData_関数拠点!D7) -> 6 | E9: =IF(RawData_関数拠点!E7="","", RawData_関数拠点!E7) -> 258.5 | F9: =IF(RawData_関数拠点!F7="","", RawData_関数拠点!F7) -> 0.037684047
A10: =IF(RawData_関数拠点!A8="","", RawData_関数拠点!A8) -> 福岡 | B10: =IF(RawData_関数拠点!B8="","", RawData_関数拠点!B8) -> 4006 | C10: =IF(RawData_関数拠点!C8="","", RawData_関数拠点!C8) -> 143.1 | D10: =IF(RawData_関数拠点!D8="","", RawData_関数拠点!D8) -> 7 | E10: =IF(RawData_関数拠点!E8="","", RawData_関数拠点!E8) -> 572.3 | F10: =IF(RawData_関数拠点!F8="","", RawData_関数拠点!F8) -> 0.097332232
A11: =IF(RawData_関数拠点!A9="","", RawData_関数拠点!A9) -> 岡山 | B11: =IF(RawData_関数拠点!B9="","", RawData_関数拠点!B9) -> 4460 | C11: =IF(RawData_関数拠点!C9="","", RawData_関数拠点!C9) -> 159.3 | D11: =IF(RawData_関数拠点!D9="","", RawData_関数拠点!D9) -> 8 | E11: =IF(RawData_関数拠点!E9="","", RawData_関数拠点!E9) -> 557.5 | F11: =IF(RawData_関数拠点!F9="","", RawData_関数拠点!F9) -> 0.10836289
A12: =IF(RawData_関数拠点!A10="","", RawData_関数拠点!A10) -> 名古屋 | B12: =IF(RawData_関数拠点!B10="","", RawData_関数拠点!B10) -> 1940 | C12: =IF(RawData_関数拠点!C10="","", RawData_関数拠点!C10) -> 69.3 | D12: =IF(RawData_関数拠点!D10="","", RawData_関数拠点!D10) -> 6 | E12: =IF(RawData_関数拠点!E10="","", RawData_関数拠点!E10) -> 323.3 | F12: =IF(RawData_関数拠点!F10="","", RawData_関数拠点!F10) -> 0.047135429
A13: =IF(RawData_関数拠点!A11="","", RawData_関数拠点!A11) -> 仙台 | B13: =IF(RawData_関数拠点!B11="","", RawData_関数拠点!B11) -> 4619 | C13: =IF(RawData_関数拠点!C11="","", RawData_関数拠点!C11) -> 165 | D13: =IF(RawData_関数拠点!D11="","", RawData_関数拠点!D11) -> 8 | E13: =IF(RawData_関数拠点!E11="","", RawData_関数拠点!E11) -> 577.4 | F13: =IF(RawData_関数拠点!F11="","", RawData_関数拠点!F11) -> 0.11222606
A14: =IF(RawData_関数拠点!A12="","", RawData_関数拠点!A12) -> 流山 | B14: =IF(RawData_関数拠点!B12="","", RawData_関数拠点!B12) -> 695 | C14: =IF(RawData_関数拠点!C12="","", RawData_関数拠点!C12) -> 24.8 | D14: =IF(RawData_関数拠点!D12="","", RawData_関数拠点!D12) -> 4 | E14: =IF(RawData_関数拠点!E12="","", RawData_関数拠点!E12) -> 173.8 | F14: =IF(RawData_関数拠点!F12="","", RawData_関数拠点!F12) -> 0.016886146
A15: =IF(RawData_関数拠点!A13="","", RawData_関数拠点!A13) -> 本社 | B15: =IF(RawData_関数拠点!B13="","", RawData_関数拠点!B13) -> 0 | C15: =IF(RawData_関数拠点!C13="","", RawData_関数拠点!C13) -> 0 | D15: =IF(RawData_関数拠点!D13="","", RawData_関数拠点!D13) -> 0 | E15: =IF(RawData_関数拠点!E13="","", RawData_関数拠点!E13) -> 0 | F15: =IF(RawData_関数拠点!F13="","", RawData_関数拠点!F13) -> 0
... A53: =IF(RawData_関数拠点!A51="","", RawData_関数拠点!A51) | B53: =IF(RawData_関数拠点!B51="","", RawData_関数拠点!B51) | C53: =IF(RawData_関数拠点!C51="","", RawData_関数拠点!C51) | D53: =IF(RawData_関数拠点!D51="","", RawData_関数拠点!D51) | E53: =IF(RawData_関数拠点!E51="","", RawData_関数拠点!E51) | F53: =IF(RawData_関数拠点!F51="","", RawData_関数拠点!F51)

Sheet RawData_関数拠点
A1: 拠点名 | B1: 2025年11月から外線のみ | C1: 外線のみ | D1: 人員 | E1: 1人当たり／月 | F1: 全体からの比率
A2: 東京 | B2: 5751 | C2: 205.4 | D2: 14 | E2: 410.8 | F2: 0.13972982
A3: 横浜 | B3: 6635 | C3: 237 | D3: 12 | E3: 552.9 | F3: 0.16120803
A4: 埼玉 | B4: 5597 | C4: 199.9 | D4: 11 | E4: 508.8 | F4: 0.13598814
A5: 滋賀 | B5: 1773 | C5: 63.3 | D5: 4 | E5: 443.3 | F5: 0.043077895
A6: 大阪 | B6: 212 | C6: 7.6 | D6: 6 | E6: 35.3 | F6: 0.005150882
A7: 千葉 | B7: 1551 | C7: 55.4 | D7: 6 | E7: 258.5 | F7: 0.037684047
A8: 福岡 | B8: 4006 | C8: 143.1 | D8: 7 | E8: 572.3 | F8: 0.097332232
A9: 岡山 | B9: 4460 | C9: 159.3 | D9: 8 | E9: 557.5 | F9: 0.10836289
A10: 名古屋 | B10: 1940 | C10: 69.3 | D10: 6 | E10: 323.3 | F10: 0.047135429
A11: 仙台 | B11: 4619 | C11: 165 | D11: 8 | E11: 577.4 | F11: 0.11222606
A12: 流山 | B12: 695 | C12: 24.8 | D12: 4 | E12: 173.8 | F12: 0.016886146
A13: 本社 | B13: 0 | C13: 0 | D13: 0 | E13: 0 | F13: 0
... A33: MF大阪 | B33: 1766 | C33: 63.1 | D33: 22 | E33: 80.3 | F33: 0.042907819

Sheet Report_時短
A1: 4. 時短勤務者
A3: 氏名 | B3: 部署 | C3: 勤務時間 | D3: 係数 | E3: 外線(実績) | F3: 受注(見込)
A4: =IF(RawData_時短!A2="","", RawData_時短!A2) -> 玉腰 千恵 | B4: =IF(RawData_時短!B2="","", RawData_時短!B2) -> 名古屋営業所(業務) | C4: =IF(RawData_時短!C2="","", RawData_時短!C2) -> 5.8 | D4: =IF(RawData_時短!D2="","", RawData_時短!D2) -> 1.4 | E4: =IF(RawData_時短!E2="","", RawData_時短!E2) -> 388 | F4: =IF(RawData_時短!F2="","", RawData_時短!F2) -> 539.3
A5: =IF(RawData_時短!A3="","", RawData_時短!A3) -> 石川 恵理 | B5: =IF(RawData_時短!B3="","", RawData_時短!B3) -> 埼玉支店(業務) | C5: =IF(RawData_時短!C3="","", RawData_時短!C3) -> 6.3 | D5: =IF(RawData_時短!D3="","", RawData_時短!D3) -> 1.3 | E5: =IF(RawData_時短!E3="","", RawData_時短!E3) -> 986 | F5: =IF(RawData_時短!F3="","", RawData_時短!F3) -> 1262.1
A6: =IF(RawData_時短!A4="","", RawData_時短!A4) -> 矢島 静音 | B6: =IF(RawData_時短!B4="","", RawData_時短!B4) -> 埼玉支店(業務) | C6: =IF(RawData_時短!C4="","", RawData_時短!C4) -> 6 | D6: =IF(RawData_時短!D4="","", RawData_時短!D4) -> 1.3 | E6: =IF(RawData_時短!E4="","", RawData_時短!E4) -> 627 | F6: =IF(RawData_時短!F4="","", RawData_時短!F4) -> 833.9
A7: =IF(RawData_時短!A5="","", RawData_時短!A5) -> 河原 由布子 | B7: =IF(RawData_時短!B5="","", RawData_時短!B5) -> 岡山営業所(業務) | C7: =IF(RawData_時短!C5="","", RawData_時短!C5) -> 6 | D7: =IF(RawData_時短!D5="","", RawData_時短!D5) -> 1.3 | E7: =IF(RawData_時短!E5="","", RawData_時短!E5) -> 801 | F7: =IF(RawData_時短!F5="","", RawData_時短!F5) -> 1065.3
A8: =IF(RawData_時短!A6="","", RawData_時短!A6) | B8: =IF(RawData_時短!B6="","", RawData_時短!B6) | C8: =IF(RawData_時短!C6="","", RawData_時短!C6) | D8: =IF(RawData_時短!D6="","", RawData_時短!D6) | E8: =IF(RawData_時短!E6="","", RawData_時短!E6) | F8: =IF(RawData_時短!F6="","", RawData_時短!F6)
A9: =IF(RawData_時短!A7="","", RawData_時短!A7) | B9: =IF(RawData_時短!B7="","", RawData_時短!B7) | C9: =IF(RawData_時短!C7="","", RawData_時短!C7) | D9: =IF(RawData_時短!D7="","", RawData_時短!D7) | E9: =IF(RawData_時短!E7="","", RawData_時短!E7) | F9: =IF(RawData_時短!F7="","", RawData_時短!F7)
A10: =IF(RawData_時短!A8="","", RawData_時短!A8) | B10: =IF(RawData_時短!B8="","", RawData_時短!B8) | C10: =IF(RawData_時短!C8="","", RawData_時短!C8) | D10: =IF(RawData_時短!D8="","", RawData_時短!D8) | E10: =IF(RawData_時短!E8="","", RawData_時短!E8) | F10: =IF(RawData_時短!F8="","", RawData_時短!F8)
A11: =IF(RawData_時短!A9="","", RawData_時短!A9) | B11: =IF(RawData_時短!B9="","", RawData_時短!B9) | C11: =IF(RawData_時短!C9="","", RawData_時短!C9) | D11: =IF(RawData_時短!D9="","", RawData_時短!D9) | E11: =IF(RawData_時短!E9="","", RawData_時短!E9) | F11: =IF(RawData_時短!F9="","", RawData_時短!F9)
A12: =IF(RawData_時短!A10="","", RawData_時短!A10) | B12: =IF(RawData_時短!B10="","", RawData_時短!B10) | C12: =IF(RawData_時短!C10="","", RawData_時短!C10) | D12: =IF(RawData_時短!D10="","", RawData_時短!D10) | E12: =IF(RawData_時短!E10="","", RawData_時短!E10) | F12: =IF(RawData_時短!F10="","", RawData_時短!F10)
A13: =IF(RawData_時短!A11="","", RawData_時短!A11) | B13: =IF(RawData_時短!B11="","", RawData_時短!B11) | C13: =IF(RawData_時短!C11="","", RawData_時短!C11) | D13: =IF(RawData_時短!D11="","", RawData_時短!D11) | E13: =IF(RawData_時短!E11="","", RawData_時短!E11) | F13: =IF(RawData_時短!F11="","", RawData_時短!F11)
A14: =IF(RawData_時短!A12="","", RawData_時短!A12) | B14: =IF(RawData_時短!B12="","", RawData_時短!B12) | C14: =IF(RawData_時短!C12="","", RawData_時短!C12) | D14: =IF(RawData_時短!D12="","", RawData_時短!D12) | E14: =IF(RawData_時短!E12="","", RawData_時短!E12) | F14: =IF(RawData_時短!F12="","", RawData_時短!F12)
A15: =IF(RawData_時短!A13="","", RawData_時短!A13) | B15: =IF(RawData_時短!B13="","", RawData_時短!B13) | C15: =IF(RawData_時短!C13="","", RawData_時短!C13) | D15: =IF(RawData_時短!D13="","", RawData_時短!D13) | E15: =IF(RawData_時短!E13="","", RawData_時短!E13) | F15: =IF(RawData_時短!F13="","", RawData_時短!F13)
... A53: =IF(RawData_時短!A51="","", RawData_時短!A51) | B53: =IF(RawData_時短!B51="","", RawData_時短!B51) | C53: =IF(RawData_時短!C51="","", RawData_時短!C51) | D53: =IF(RawData_時短!D51="","", RawData_時短!D51) | E53: =IF(RawData_時短!E51="","", RawData_時短!E51) | F53: =IF(RawData_時短!F51="","", RawData_時短!F51)

Sheet RawData_時短
A1: 氏名 | B1: 部署 | C1: 勤務時間 | D1: 係数 | E1: 外線(実績) | F1: 受注(見込)
A2: 玉腰 千恵 | B2: 名古屋営業所(業務) | C2: 5.8 | D2: 1.4 | E2: 388 | F2: 539.3
A3: 石川 恵理 | B3: 埼玉支店(業務) | C3: 6.3 | D3: 1.3 | E3: 986 | F3: 1262.1
A4: 矢島 静音 | B4: 埼玉支店(業務) | C4: 6 | D4: 1.3 | E4: 627 | F4: 833.9
A5: 河原 由布子 | B5: 岡山営業所(業務) | C5: 6 | D5: 1.3 | E5: 801 | F5: 1065.3

Sheet Report_営業集計
A1: 5. 営業時間内(Final) 集計
A3: 拠点名 | B3: 営業時間内_外線のみ | C3: 人員 | D3: 1人当たり／月 | E3: 全体からの比率
A4: =IF(RawData_営業集計!A2="","", RawData_営業集計!A2) -> 東京 | B4: =IF(RawData_営業集計!B2="","", RawData_営業集計!B2) -> 5468 | C4: =IF(RawData_営業集計!C2="","", RawData_営業集計!C2) -> 14 | D4: =IF(RawData_営業集計!D2="","", RawData_営業集計!D2) -> 390.6 | E4: =IF(RawData_営業集計!E2="","", RawData_営業集計!E2) -> 0.13577672
A5: =IF(RawData_営業集計!A3="","", RawData_営業集計!A3) -> 横浜 | B5: =IF(RawData_営業集計!B3="","", RawData_営業集計!B3) -> 6594 | C5: =IF(RawData_営業集計!C3="","", RawData_営業集計!C3) -> 12 | D5: =IF(RawData_営業集計!D3="","", RawData_営業集計!D3) -> 549.5 | E5: =IF(RawData_営業集計!E3="","", RawData_営業集計!E3) -> 0.16373659
A6: =IF(RawData_営業集計!A4="","", RawData_営業集計!A4) -> 埼玉 | B6: =IF(RawData_営業集計!B4="","", RawData_営業集計!B4) -> 5504 | C6: =IF(RawData_営業集計!C4="","", RawData_営業集計!C4) -> 11 | D6: =IF(RawData_営業集計!D4="","", RawData_営業集計!D4) -> 500.4 | E6: =IF(RawData_営業集計!E4="","", RawData_営業集計!E4) -> 0.13667064
A7: =IF(RawData_営業集計!A5="","", RawData_営業集計!A5) -> 滋賀 | B7: =IF(RawData_営業集計!B5="","", RawData_営業集計!B5) -> 1768 | C7: =IF(RawData_営業集計!C5="","", RawData_営業集計!C5) -> 4 | D7: =IF(RawData_営業集計!D5="","", RawData_営業集計!D5) -> 442 | E7: =IF(RawData_営業集計!E5="","", RawData_営業集計!E5) -> 0.04390147
A8: =IF(RawData_営業集計!A6="","", RawData_営業集計!A6) -> 大阪 | B8: =IF(RawData_営業集計!B6="","", RawData_営業集計!B6) -> 174 | C8: =IF(RawData_営業集計!C6="","", RawData_営業集計!C6) -> 6 | D8: =IF(RawData_営業集計!D6="","", RawData_営業集計!D6) -> 29 | E8: =IF(RawData_営業集計!E6="","", RawData_営業集計!E6) -> 0.0043206198
A9: =IF(RawData_営業集計!A7="","", RawData_営業集計!A7) -> 千葉 | B9: =IF(RawData_営業集計!B7="","", RawData_営業集計!B7) -> 1550 | C9: =IF(RawData_営業集計!C7="","", RawData_営業集計!C7) -> 6 | D9: =IF(RawData_営業集計!D7="","", RawData_営業集計!D7) -> 258.3 | E9: =IF(RawData_営業集計!E7="","", RawData_営業集計!E7) -> 0.03848828
A10: =IF(RawData_営業集計!A8="","", RawData_営業集計!A8) -> 福岡 | B10: =IF(RawData_営業集計!B8="","", RawData_営業集計!B8) -> 3933 | C10: =IF(RawData_営業集計!C8="","", RawData_営業集計!C8) -> 7 | D10: =IF(RawData_営業集計!D8="","", RawData_営業集計!D8) -> 561.9 | E10: =IF(RawData_営業集計!E8="","", RawData_営業集計!E8) -> 0.097660906
A11: =IF(RawData_営業集計!A9="","", RawData_営業集計!A9) -> 岡山 | B11: =IF(RawData_営業集計!B9="","", RawData_営業集計!B9) -> 4414 | C11: =IF(RawData_営業集計!C9="","", RawData_営業集計!C9) -> 8 | D11: =IF(RawData_営業集計!D9="","", RawData_営業集計!D9) -> 551.8 | E11: =IF(RawData_営業集計!E9="","", RawData_営業集計!E9) -> 0.10960469
A12: =IF(RawData_営業集計!A10="","", RawData_営業集計!A10) -> 名古屋 | B12: =IF(RawData_営業集計!B10="","", RawData_営業集計!B10) -> 1932 | C12: =IF(RawData_営業集計!C10="","", RawData_営業集計!C10) -> 6 | D12: =IF(RawData_営業集計!D10="","", RawData_営業集計!D10) -> 322 | E12: =IF(RawData_営業集計!E10="","", RawData_営業集計!E10) -> 0.047973778
A13: =IF(RawData_営業集計!A11="","", RawData_営業集計!A11) -> 仙台 | B13: =IF(RawData_営業集計!B11="","", RawData_営業集計!B11) -> 4409 | C13: =IF(RawData_営業集計!C11="","", RawData_営業集計!C11) -> 8 | D13: =IF(RawData_営業集計!D11="","", RawData_営業集計!D11) -> 551.1 | E13: =IF(RawData_営業集計!E11="","", RawData_営業集計!E11) -> 0.10948053
A14: =IF(RawData_営業集計!A12="","", RawData_営業集計!A12) -> 流山 | B14: =IF(RawData_営業集計!B12="","", RawData_営業集計!B12) -> 673 | C14: =IF(RawData_営業集計!C12="","", RawData_営業集計!C12) -> 4 | D14: =IF(RawData_営業集計!D12="","", RawData_営業集計!D12) -> 168.3 | E14: =IF(RawData_営業集計!E12="","", RawData_営業集計!E12) -> 0.016711363
A15: =IF(RawData_営業集計!A13="","", RawData_営業集計!A13) -> 本社 | B15: =IF(RawData_営業集計!B13="","", RawData_営業集計!B13) -> 0 | C15: =IF(RawData_営業集計!C13="","", RawData_営業集計!C13) -> 0 | D15: =IF(RawData_営業集計!D13="","", RawData_営業集計!D13) -> 0 | E15: =IF(RawData_営業集計!E13="","", RawData_営業集計!E13) -> 0
... A53: =IF(RawData_営業集計!A51="","", RawData_営業集計!A51) | B53: =IF(RawData_営業集計!B51="","", RawData_営業集計!B51) | C53: =IF(RawData_営業集計!C51="","", RawData_営業集計!C51) | D53: =IF(RawData_営業集計!D51="","", RawData_営業集計!D51) | E53: =IF(RawData_営業集計!E51="","", RawData_営業集計!E51)

Sheet RawData_営業集計
A1: 拠点名 | B1: 営業時間内_外線のみ | C1: 人員 | D1: 1人当たり／月 | E1: 全体からの比率
A2: 東京 | B2: 5468 | C2: 14 | D2: 390.6 | E2: 0.13577672
A3: 横浜 | B3: 6594 | C3: 12 | D3: 549.5 | E3: 0.16373659
A4: 埼玉 | B4: 5504 | C4: 11 | D4: 500.4 | E4: 0.13667064
A5: 滋賀 | B5: 1768 | C5: 4 | D5: 442 | E5: 0.04390147
A6: 大阪 | B6: 174 | C6: 6 | D6: 29 | E6: 0.0043206198
A7: 千葉 | B7: 1550 | C7: 6 | D7: 258.3 | E7: 0.03848828
A8: 福岡 | B8: 3933 | C8: 7 | D8: 561.9 | E8: 0.097660906
A9: 岡山 | B9: 4414 | C9: 8 | D9: 551.8 | E9: 0.10960469
A10: 名古屋 | B10: 1932 | C10: 6 | D10: 322 | E10: 0.047973778
A11: 仙台 | B11: 4409 | C11: 8 | D11: 551.1 | E11: 0.10948053
A12: 流山 | B12: 673 | C12: 4 | D12: 168.3 | E12: 0.016711363
A13: 本社 | B13: 0 | C13: 0 | D13: 0 | E13: 0
... A33: MF大阪 | B33: 1760 | C33: 22 | D33: 80 | E33: 0.043702821

Sheet Report_時間内
A1: 6. 営業時間内(Target) 集計
A3: 拠点 | B3: 内線_入電 | C3: 内線_着電 | D3: 内線_応答率 | E3: 外線_入電 | F3: 外線_着電 | G3: 外線_応答率
A4: =IF(RawData_時間内!A2="","", RawData_時間内!A2) -> 東京 | B4: =IF(RawData_時間内!B2="","", RawData_時間内!B2) -> 431 | C4: =IF(RawData_時間内!C2="","", RawData_時間内!C2) -> 350 | D4: =IF(RawData_時間内!D2="","", RawData_時間内!D2) -> 0.81206497 | E4: =IF(RawData_時間内!E2="","", RawData_時間内!E2) -> 5527 | F4: =IF(RawData_時間内!F2="","", RawData_時間内!F2) -> 5415 | G4: =IF(RawData_時間内!G2="","", RawData_時間内!G2) -> 0.97973584
A5: =IF(RawData_時間内!A3="","", RawData_時間内!A3) -> 横浜 | B5: =IF(RawData_時間内!B3="","", RawData_時間内!B3) -> 484 | C5: =IF(RawData_時間内!C3="","", RawData_時間内!C3) -> 383 | D5: =IF(RawData_時間内!D3="","", RawData_時間内!D3) -> 0.79132231 | E5: =IF(RawData_時間内!E3="","", RawData_時間内!E3) -> 6455 | F5: =IF(RawData_時間内!F3="","", RawData_時間内!F3) -> 6253 | G5: =IF(RawData_時間内!G3="","", RawData_時間内!G3) -> 0.96870643
A6: =IF(RawData_時間内!A4="","", RawData_時間内!A4) -> 埼玉 | B6: =IF(RawData_時間内!B4="","", RawData_時間内!B4) -> 397 | C6: =IF(RawData_時間内!C4="","", RawData_時間内!C4) -> 286 | D6: =IF(RawData_時間内!D4="","", RawData_時間内!D4) -> 0.72040302 | E6: =IF(RawData_時間内!E4="","", RawData_時間内!E4) -> 4978 | F6: =IF(RawData_時間内!F4="","", RawData_時間内!F4) -> 4840 | G6: =IF(RawData_時間内!G4="","", RawData_時間内!G4) -> 0.97227802
A7: =IF(RawData_時間内!A5="","", RawData_時間内!A5) -> 滋賀 | B7: =IF(RawData_時間内!B5="","", RawData_時間内!B5) -> 107 | C7: =IF(RawData_時間内!C5="","", RawData_時間内!C5) -> 86 | D7: =IF(RawData_時間内!D5="","", RawData_時間内!D5) -> 0.80373832 | E7: =IF(RawData_時間内!E5="","", RawData_時間内!E5) -> 1659 | F7: =IF(RawData_時間内!F5="","", RawData_時間内!F5) -> 1619 | G7: =IF(RawData_時間内!G5="","", RawData_時間内!G5) -> 0.97588909
A8: =IF(RawData_時間内!A6="","", RawData_時間内!A6) -> 大阪 | B8: =IF(RawData_時間内!B6="","", RawData_時間内!B6) -> 310 | C8: =IF(RawData_時間内!C6="","", RawData_時間内!C6) -> 249 | D8: =IF(RawData_時間内!D6="","", RawData_時間内!D6) -> 0.80322581 | E8: =IF(RawData_時間内!E6="","", RawData_時間内!E6) -> 1241 | F8: =IF(RawData_時間内!F6="","", RawData_時間内!F6) -> 1130 | G8: =IF(RawData_時間内!G6="","", RawData_時間内!G6) -> 0.910556
A9: =IF(RawData_時間内!A7="","", RawData_時間内!A7) -> 千葉 | B9: =IF(RawData_時間内!B7="","", RawData_時間内!B7) -> 377 | C9: =IF(RawData_時間内!C7="","", RawData_時間内!C7) -> 298 | D9: =IF(RawData_時間内!D7="","", RawData_時間内!D7) -> 0.79045093 | E9: =IF(RawData_時間内!E7="","", RawData_時間内!E7) -> 1997 | F9: =IF(RawData_時間内!F7="","", RawData_時間内!F7) -> 1892 | G9: =IF(RawData_時間内!G7="","", RawData_時間内!G7) -> 0.94742113
A10: =IF(RawData_時間内!A8="","", RawData_時間内!A8) -> 福岡 | B10: =IF(RawData_時間内!B8="","", RawData_時間内!B8) -> 1311 | C10: =IF(RawData_時間内!C8="","", RawData_時間内!C8) -> 1170 | D10: =IF(RawData_時間内!D8="","", RawData_時間内!D8) -> 0.89244851 | E10: =IF(RawData_時間内!E8="","", RawData_時間内!E8) -> 4011 | F10: =IF(RawData_時間内!F8="","", RawData_時間内!F8) -> 3753 | G10: =IF(RawData_時間内!G8="","", RawData_時間内!G8) -> 0.93567689
A11: =IF(RawData_時間内!A9="","", RawData_時間内!A9) -> 岡山 | B11: =IF(RawData_時間内!B9="","", RawData_時間内!B9) -> 400 | C11: =IF(RawData_時間内!C9="","", RawData_時間内!C9) -> 263 | D11: =IF(RawData_時間内!D9="","", RawData_時間内!D9) -> 0.6575 | E11: =IF(RawData_時間内!E9="","", RawData_時間内!E9) -> 2813 | F11: =IF(RawData_時間内!F9="","", RawData_時間内!F9) -> 2652 | G11: =IF(RawData_時間内!G9="","", RawData_時間内!G9) -> 0.94276573
A12: =IF(RawData_時間内!A10="","", RawData_時間内!A10) -> 名古屋 | B12: =IF(RawData_時間内!B10="","", RawData_時間内!B10) -> 629 | C12: =IF(RawData_時間内!C10="","", RawData_時間内!C10) -> 594 | D12: =IF(RawData_時間内!D10="","", RawData_時間内!D10) -> 0.94435612 | E12: =IF(RawData_時間内!E10="","", RawData_時間内!E10) -> 1987 | F12: =IF(RawData_時間内!F10="","", RawData_時間内!F10) -> 1932 | G12: =IF(RawData_時間内!G10="","", RawData_時間内!G10) -> 0.97232008
A13: =IF(RawData_時間内!A11="","", RawData_時間内!A11) -> 仙台 | B13: =IF(RawData_時間内!B11="","", RawData_時間内!B11) -> 360 | C13: =IF(RawData_時間内!C11="","", RawData_時間内!C11) -> 214 | D13: =IF(RawData_時間内!D11="","", RawData_時間内!D11) -> 0.59444444 | E13: =IF(RawData_時間内!E11="","", RawData_時間内!E11) -> 4273 | F13: =IF(RawData_時間内!F11="","", RawData_時間内!F11) -> 4163 | G13: =IF(RawData_時間内!G11="","", RawData_時間内!G11) -> 0.97425696
A14: =IF(RawData_時間内!A12="","", RawData_時間内!A12) -> 流山 | B14: =IF(RawData_時間内!B12="","", RawData_時間内!B12) -> 468 | C14: =IF(RawData_時間内!C12="","", RawData_時間内!C12) -> 322 | D14: =IF(RawData_時間内!D12="","", RawData_時間内!D12) -> 0.68803419 | E14: =IF(RawData_時間内!E12="","", RawData_時間内!E12) -> 752 | F14: =IF(RawData_時間内!F12="","", RawData_時間内!F12) -> 726 | G14: =IF(RawData_時間内!G12="","", RawData_時間内!G12) -> 0.96542553
A15: =IF(RawData_時間内!A13="","", RawData_時間内!A13) -> 本社 | B15: =IF(RawData_時間内!B13="","", RawData_時間内!B13) -> 223 | C15: =IF(RawData_時間内!C13="","", RawData_時間内!C13) -> 207 | D15: =IF(RawData_時間内!D13="","", RawData_時間内!D13) -> 0.92825112 | E15: =IF(RawData_時間内!E13="","", RawData_時間内!E13) -> 1017 | F15: =IF(RawData_時間内!F13="","", RawData_時間内!F13) -> 961 | G15: =IF(RawData_時間内!G13="","", RawData_時間内!G13) -> 0.94493609
... A53: =IF(RawData_時間内!A51="","", RawData_時間内!A51) | B53: =IF(RawData_時間内!B51="","", RawData_時間内!B51) | C53: =IF(RawData_時間内!C51="","", RawData_時間内!C51) | D53: =IF(RawData_時間内!D51="","", RawData_時間内!D51) | E53: =IF(RawData_時間内!E51="","", RawData_時間内!E51) | F53: =IF(RawData_時間内!F51="","", RawData_時間内!F51) | G53: =IF(RawData_時間内!G51="","", RawData_時間内!G51)

Sheet RawData_時間内
A1: 拠点 | B1: 内線_入電 | C1: 内線_着電 | D1: 内線_応答率 | E1: 外線_入電 | F1: 外線_着電 | G1: 外線_応答率
A2: 東京 | B2: 431 | C2: 350 | D2: 0.81206497 | E2: 5527 | F2: 5415 | G2: 0.97973584
A3: 横浜 | B3: 484 | C3: 383 | D3: 0.79132231 | E3: 6455 | F3: 6253 | G3: 0.96870643
A4: 埼玉 | B4: 397 | C4: 286 | D4: 0.72040302 | E4: 4978 | F4: 4840 | G4: 0.97227802
A5: 滋賀 | B5: 107 | C5: 86 | D5: 0.80373832 | E5: 1659 | F5: 1619 | G5: 0.97588909
A6: 大阪 | B6: 310 | C6: 249 | D6: 0.80322581 | E6: 1241 | F6: 1130 | G6: 0.910556
A7: 千葉 | B7: 377 | C7: 298 | D7: 0.79045093 | E7: 1997 | F7: 1892 | G7: 0.94742113
A8: 福岡 | B8: 1311 | C8: 1170 | D8: 0.89244851 | E8: 4011 | F8: 3753 | G8: 0.93567689
A9: 岡山 | B9: 400 | C9: 263 | D9: 0.6575 | E9: 2813 | F9: 2652 | G9: 0.94276573
A10: 名古屋 | B10: 629 | C10: 594 | D10: 0.94435612 | E10: 1987 | F10: 1932 | G10: 0.97232008
A11: 仙台 | B11: 360 | C11: 214 | D11: 0.59444444 | E11: 4273 | F11: 4163 | G11: 0.97425696
A12: 流山 | B12: 468 | C12: 322 | D12: 0.68803419 | E12: 752 | F12: 726 | G12: 0.96542553
A13: 本社 | B13: 223 | C13: 207 | D13: 0.92825112 | E13: 1017 | F13: 961 | G13: 0.94493609
... A34: 合計 | B34: 7448 | C34: 5812 | D34: 0.78034372 | E34: 41971 | F34: 40272 | G34: 0.95951967
